Workbook

Sheet RQ1
A1: RQ1 | B1: Are narrative titles enough or models benefit from an extended narrative description? | M1: ALL | P1: EN | Q1: HI | R1: PT | S1: BG | T1: RU | U1: Total
A2: dipro | B2: calme | D2: gemma | F2: exaone | H2: granite | L2: Number of models better than no_no | O2: =COUNTIF(B5:I5,"<0") + COUNTIF(B7:I7,"<0") + COUNTIF(B9:I9,"<0") + COUNTIF(B11:I11,"<0") + COUNTIF(B13:I13,"<0") + COUNTIF(B15:I15,"<0") + COUNTIF(B17:I17,"<0") + COUNTIF(B24:I24,"<0") + COUNTIF(B26:I26,"<0") + COUNTIF(B28:I28,"<0") + COUNTIF(B30:I30,"<0") + COUNTIF(B32:I32,"<0") + COUNTIF(B34:I34,"<0") + COUNTIF(B36:I36,"<0") + COUNTIF(B43:I43,"<0") + COUNTIF(B45:I45,"<0") + COUNTIF(B47:I47,"<0") + COUNTIF(B49:I49,"<0") + COUNTIF(B51:I51,"<0") + COUNTIF(B53:I53,"<0") + COUNTIF(B55:I55,"<0") + COUNTIF(B62:I62,"<0") + COUNTIF(B64:I64,"<0") + COUNTIF(B66:I66,"<0") + COUNTIF(B68:I68,"<0") + COUNTIF(B69:I69,"<0") + COUNTIF(B70:I70,"<0") + COUNTIF(B72:I72,"<0") + COUNTIF(B74:I74,"<0") -> 46 | P2: 52 | Q2: 66 | R2: 34 | S2: 53 | T2: 46 | U2: =SUM(P2:T2) -> 251
A3: no_no | B3: =IFERROR(__xludf.DUMMYFUNCTION("FILTER(Dipromats!C$3:C$101, REGEXMATCH(Dipromats!$A$3:$A$101, ""(?i)"" & $A3) )"),0.634504615288617) -> 0.63450462 | C3: =IFERROR(__xludf.DUMMYFUNCTION("FILTER(Dipromats!D$3:D$101, REGEXMATCH(Dipromats!$A$3:$A$101, ""(?i)"" & $A3) )"),0.583394320061881) -> 0.58339432 | D3: =IFERROR(__xludf.DUMMYFUNCTION("FILTER(Dipromats!E$3:E$101, REGEXMATCH(Dipromats!$A$3:$A$101, ""(?i)"" & $A3) )"),0.612546907727468) -> 0.61254691 | E3: =IFERROR(__xludf.DUMMYFUNCTION("FILTER(Dipromats!F$3:F$101, REGEXMATCH(Dipromats!$A$3:$A$101, ""(?i)"" & $A3) )"),0.564694414756619) -> 0.56469441 | F3: =IFERROR(__xludf.DUMMYFUNCTION("FILTER(Dipromats!G$3:G$101, REGEXMATCH(Dipromats!$A$3:$A$101, ""(?i)"" & $A3) )"),0.551936514723647) -> 0.55193651 | G3: =IFERROR(__xludf.DUMMYFUNCTION("FILTER(Dipromats!H$3:H$101, REGEXMATCH(Dipromats!$A$3:$A$101, ""(?i)"" & $A3) )"),0.498994997427713) -> 0.498995 | H3: =IFERROR(__xludf.DUMMYFUNCTION("FILTER(Dipromats!I$3:I$101, REGEXMATCH(Dipromats!$A$3:$A$101, ""(?i)"" & $A3) )"),0.333605146281453) -> 0.33360515 | I3: =IFERROR(__xludf.DUMMYFUNCTION("FILTER(Dipromats!J$3:J$101, REGEXMATCH(Dipromats!$A$3:$A$101, ""(?i)"" & $A3) )"),0.367508834746624) -> 0.36750883 | L3: Number of models worse than no_no | O3: =COUNTIF(B5:I5,">0") + COUNTIF(B7:I7,">0") + COUNTIF(B9:I9,">0") + COUNTIF(B11:I11,">0") + COUNTIF(B13:I13,">0") + COUNTIF(B15:I15,">0") + COUNTIF(B17:I17,">0") + COUNTIF(B24:I24,">0") + COUNTIF(B26:I26,">0") + COUNTIF(B28:I28,">0") + COUNTIF(B30:I30,">0") + COUNTIF(B32:I32,">0") + COUNTIF(B34:I34,">0") + COUNTIF(B36:I36,">0") + COUNTIF(B43:I43,">0") + COUNTIF(B45:I45,">0") + COUNTIF(B47:I47,">0") + COUNTIF(B49:I49,">0") + COUNTIF(B51:I51,">0") + COUNTIF(B53:I53,">0") + COUNTIF(B55:I55,">0") + COUNTIF(B62:I62,">0") + COUNTIF(B64:I64,">0") + COUNTIF(B66:I66,">0") + COUNTIF(B68:I68,">0") + COUNTIF(B69:I69,">0") + COUNTIF(B70:I70,">0") + COUNTIF(B72:I72,">0") + COUNTIF(B74:I74,">0") -> 164 | P3: 160 | Q3: 144 | R3: 176 | S3: 157 | T3: 164 | U3: =SUM(P3:T3) -> 801
A4: original_original | B4: =IFERROR(__xludf.DUMMYFUNCTION("FILTER(Dipromats!C$3:C$101, REGEXMATCH(Dipromats!$A$3:$A$101, ""(?i)"" & $A4) )"),0.638654812715595) -> 0.63865481 | C4: =IFERROR(__xludf.DUMMYFUNCTION("FILTER(Dipromats!D$3:D$101, REGEXMATCH(Dipromats!$A$3:$A$101, ""(?i)"" & $A4) )"),0.613462791622532) -> 0.61346279 | D4: =IFERROR(__xludf.DUMMYFUNCTION("FILTER(Dipromats!E$3:E$101, REGEXMATCH(Dipromats!$A$3:$A$101, ""(?i)"" & $A4) )"),0.624175131263906) -> 0.62417513 | E4: =IFERROR(__xludf.DUMMYFUNCTION("FILTER(Dipromats!F$3:F$101, REGEXMATCH(Dipromats!$A$3:$A$101, ""(?i)"" & $A4) )"),0.593223331315557) -> 0.59322333 | F4: =IFERROR(__xludf.DUMMYFUNCTION("FILTER(Dipromats!G$3:G$101, REGEXMATCH(Dipromats!$A$3:$A$101, ""(?i)"" & $A4) )"),0.572478446675392) -> 0.57247845 | G4: =IFERROR(__xludf.DUMMYFUNCTION("FILTER(Dipromats!H$3:H$101, REGEXMATCH(Dipromats!$A$3:$A$101, ""(?i)"" & $A4) )"),0.534765902917699) -> 0.5347659 | H4: =IFERROR(__xludf.DUMMYFUNCTION("FILTER(Dipromats!I$3:I$101, REGEXMATCH(Dipromats!$A$3:$A$101, ""(?i)"" & $A4) )"),0.335225441305954) -> 0.33522544 | I4: =IFERROR(__xludf.DUMMYFUNCTION("FILTER(Dipromats!J$3:J$101, REGEXMATCH(Dipromats!$A$3:$A$101, ""(?i)"" & $A4) )"),0.352567599779278) -> 0.3525676 | L4: Percentage of better models | O4: =(O2*100)/(O2+O3) -> 21.904762 | U4: =(U2*100)/(U2+U3) -> 23.859316
A5: delta_original | B5: =B3-B4 -> -0.0041501974 | C5: =C3-C4 -> -0.030068472 | D5: =D3-D4 -> -0.011628224 | E5: =E3-E4 -> -0.028528917 | F5: =F3-F4 -> -0.020541932 | G5: =G3-G4 -> -0.035770905 | H5: =H3-H4 -> -0.001620295 | I5: =I3-I4 -> 0.014941235 | J5: =AVERAGE(B5:I5) -> -0.014670963 | L5: Percentage of worst models | O5: =100-O4 -> 78.095238 | U5: =100-U4 -> 76.140684
A6: own_title | B6: =IFERROR(__xludf.DUMMYFUNCTION("FILTER(Dipromats!C$3:C$101, REGEXMATCH(Dipromats!$A$3:$A$101, ""(?i)"" & $A6) )"),0.621040280030557) -> 0.62104028 | C6: =IFERROR(__xludf.DUMMYFUNCTION("FILTER(Dipromats!D$3:D$101, REGEXMATCH(Dipromats!$A$3:$A$101, ""(?i)"" & $A6) )"),0.571358654012934) -> 0.57135865 | D6: =IFERROR(__xludf.DUMMYFUNCTION("FILTER(Dipromats!E$3:E$101, REGEXMATCH(Dipromats!$A$3:$A$101, ""(?i)"" & $A6) )"),0.57620875615112) -> 0.57620876 | E6: =IFERROR(__xludf.DUMMYFUNCTION("FILTER(Dipromats!F$3:F$101, REGEXMATCH(Dipromats!$A$3:$A$101, ""(?i)"" & $A6) )"),0.531274741257453) -> 0.53127474 | F6: =IFERROR(__xludf.DUMMYFUNCTION("FILTER(Dipromats!G$3:G$101, REGEXMATCH(Dipromats!$A$3:$A$101, ""(?i)"" & $A6) )"),0.506150051999198) -> 0.50615005 | G6: =IFERROR(__xludf.DUMMYFUNCTION("FILTER(Dipromats!H$3:H$101, REGEXMATCH(Dipromats!$A$3:$A$101, ""(?i)"" & $A6) )"),0.483697863941618) -> 0.48369786 | H6: =IFERROR(__xludf.DUMMYFUNCTION("FILTER(Dipromats!I$3:I$101, REGEXMATCH(Dipromats!$A$3:$A$101, ""(?i)"" & $A6) )"),0.286129356930116) -> 0.28612936 | I6: =IFERROR(__xludf.DUMMYFUNCTION("FILTER(Dipromats!J$3:J$101, REGEXMATCH(Dipromats!$A$3:$A$101, ""(?i)"" & $A6) )"),0.29837198245895) -> 0.29837198 | M6: ONLY original_original
A7: delta_own_title | B7: =B3-B6 -> 0.013464335 | C7: =C3-C6 -> 0.012035666 | D7: =D3-D6 -> 0.036338152 | E7: =E3-E6 -> 0.033419673 | F7: =F3-F6 -> 0.045786463 | G7: =G3-G6 -> 0.015297133 | H7: =H3-H6 -> 0.047475789 | I7: =I3-I6 -> 0.069136852 | J7: =AVERAGE(B7:I7) -> 0.034119258 | L7: Number of models better than no_no | O7: =COUNTIF(B5:I5,"<0") + COUNTIF(B24:I24,"<0") + COUNTIF(B43:I43,"<0") + COUNTIF(B62:I62,"<0") -> 14 | P7: 20 | Q7: 21 | R7: 15 | S7: 21 | T7: 14 | U7: =SUM(P7:T7) -> 91
A8: gpt_title | B8: =IFERROR(__xludf.DUMMYFUNCTION("FILTER(Dipromats!C$3:C$101, REGEXMATCH(Dipromats!$A$3:$A$101, ""(?i)"" & $A8) )"),0.608500522443986) -> 0.60850052 | C8: =IFERROR(__xludf.DUMMYFUNCTION("FILTER(Dipromats!D$3:D$101, REGEXMATCH(Dipromats!$A$3:$A$101, ""(?i)"" & $A8) )"),0.565727300132339) -> 0.5657273 | D8: =IFERROR(__xludf.DUMMYFUNCTION("FILTER(Dipromats!E$3:E$101, REGEXMATCH(Dipromats!$A$3:$A$101, ""(?i)"" & $A8) )"),0.583927636565709) -> 0.58392764 | E8: =IFERROR(__xludf.DUMMYFUNCTION("FILTER(Dipromats!F$3:F$101, REGEXMATCH(Dipromats!$A$3:$A$101, ""(?i)"" & $A8) )"),0.523712547832867) -> 0.52371255 | F8: =IFERROR(__xludf.DUMMYFUNCTION("FILTER(Dipromats!G$3:G$101, REGEXMATCH(Dipromats!$A$3:$A$101, ""(?i)"" & $A8) )"),0.524902705155418) -> 0.52490271 | G8: =IFERROR(__xludf.DUMMYFUNCTION("FILTER(Dipromats!H$3:H$101, REGEXMATCH(Dipromats!$A$3:$A$101, ""(?i)"" & $A8) )"),0.490732657736496) -> 0.49073266 | H8: =IFERROR(__xludf.DUMMYFUNCTION("FILTER(Dipromats!I$3:I$101, REGEXMATCH(Dipromats!$A$3:$A$101, ""(?i)"" & $A8) )"),0.267289569310955) -> 0.26728957 | I8: =IFERROR(__xludf.DUMMYFUNCTION("FILTER(Dipromats!J$3:J$101, REGEXMATCH(Dipromats!$A$3:$A$101, ""(?i)"" & $A8) )"),0.297865824391553) -> 0.29786582 | L8: Number of models worse than no_no | O8: =COUNTIF(B5:I5,">0") + COUNTIF(B24:I24,">0") + COUNTIF(B43:I43,">0") + COUNTIF(B62:I62,">0") -> 18 | P8: 12 | Q8: 11 | R8: 17 | S8: 11 | T8: 18 | U8: =SUM(P8:T8) -> 69
A9: delta_gpt_title | B9: =B3-B8 -> 0.026004093 | C9: =C3-C8 -> 0.01766702 | D9: =D3-D8 -> 0.028619271 | E9: =E3-E8 -> 0.040981867 | F9: =F3-F8 -> 0.02703381 | G9: =G3-G8 -> 0.0082623397 | H9: =H3-H8 -> 0.066315577 | I9: =I3-I8 -> 0.06964301 | J9: =AVERAGE(B9:I9) -> 0.035565873 | L9: Percentage of better models | O9: =(O7*100)/(O7+O8) -> 43.75 | U9: =(U7*100)/(U7+U8) -> 56.875
A10: own_description | B10: =IFERROR(__xludf.DUMMYFUNCTION("FILTER(Dipromats!C$3:C$101, REGEXMATCH(Dipromats!$A$3:$A$101, ""(?i)"" & $A10), NOT(REGEXMATCH(Dipromats!$A$3:$A$101, ""(?i)complete"")) )"),0.631787462260468) -> 0.63178746 | C10: =IFERROR(__xludf.DUMMYFUNCTION("FILTER(Dipromats!D$3:D$101, REGEXMATCH(Dipromats!$A$3:$A$101, ""(?i)"" & $A10), NOT(REGEXMATCH(Dipromats!$A$3:$A$101, ""(?i)complete"")) )"),0.618216042484733) -> 0.61821604 | D10: =IFERROR(__xludf.DUMMYFUNCTION("FILTER(Dipromats!E$3:E$101, REGEXMATCH(Dipromats!$A$3:$A$101, ""(?i)"" & $A10), NOT(REGEXMATCH(Dipromats!$A$3:$A$101, ""(?i)complete"")) )"),0.586439666342686) -> 0.58643967 | E10: =IFERROR(__xludf.DUMMYFUNCTION("FILTER(Dipromats!F$3:F$101, REGEXMATCH(Dipromats!$A$3:$A$101, ""(?i)"" & $A10), NOT(REGEXMATCH(Dipromats!$A$3:$A$101, ""(?i)complete"")) )"),0.569895182181278) -> 0.56989518 | F10: =IFERROR(__xludf.DUMMYFUNCTION("FILTER(Dipromats!G$3:G$101, REGEXMATCH(Dipromats!$A$3:$A$101, ""(?i)"" & $A10), NOT(REGEXMATCH(Dipromats!$A$3:$A$101, ""(?i)complete"")) )"),0.546258468663482) -> 0.54625847 | G10: =IFERROR(__xludf.DUMMYFUNCTION("FILTER(Dipromats!H$3:H$101, REGEXMATCH(Dipromats!$A$3:$A$101, ""(?i)"" & $A10), NOT(REGEXMATCH(Dipromats!$A$3:$A$101, ""(?i)complete"")) )"),0.512012998082786) -> 0.512013 | H10: =IFERROR(__xludf.DUMMYFUNCTION("FILTER(Dipromats!I$3:I$101, REGEXMATCH(Dipromats!$A$3:$A$101, ""(?i)"" & $A10), NOT(REGEXMATCH(Dipromats!$A$3:$A$101, ""(?i)complete"")) )"),0.288938661231155) -> 0.28893866 | I10: =IFERROR(__xludf.DUMMYFUNCTION("FILTER(Dipromats!J$3:J$101, REGEXMATCH(Dipromats!$A$3:$A$101, ""(?i)"" & $A10), NOT(REGEXMATCH(Dipromats!$A$3:$A$101, ""(?i)complete"")) )"),0.329512617172151) -> 0.32951262 | L10: Percentage of worst models | O10: =100-O9 -> 56.25 | U10: =100-U9 -> 43.125
A11: delta_own_description | B11: =B3-B10 -> 0.002717153 | C11: =C3-C10 -> -0.034821722 | D11: =D3-D10 -> 0.026107241 | E11: =E3-E10 -> -0.0052007674 | F11: =F3-F10 -> 0.0056780461 | G11: =G3-G10 -> -0.013018001 | H11: =H3-H10 -> 0.044666485 | I11: =I3-I10 -> 0.037996218 | J11: =AVERAGE(B11:I11) -> 0.0080155816
A12: gpt_description | B12: =IFERROR(__xludf.DUMMYFUNCTION("FILTER(Dipromats!C$3:C$101, REGEXMATCH(Dipromats!$A$3:$A$101, ""(?i)"" & $A12), NOT(REGEXMATCH(Dipromats!$A$3:$A$101, ""(?i)complete"")) )"),0.640317661477475) -> 0.64031766 | C12: =IFERROR(__xludf.DUMMYFUNCTION("FILTER(Dipromats!D$3:D$101, REGEXMATCH(Dipromats!$A$3:$A$101, ""(?i)"" & $A12), NOT(REGEXMATCH(Dipromats!$A$3:$A$101, ""(?i)complete"")) )"),0.61354665612827) -> 0.61354666 | D12: =IFERROR(__xludf.DUMMYFUNCTION("FILTER(Dipromats!E$3:E$101, REGEXMATCH(Dipromats!$A$3:$A$101, ""(?i)"" & $A12), NOT(REGEXMATCH(Dipromats!$A$3:$A$101, ""(?i)complete"")) )"),0.613750839783722) -> 0.61375084 | E12: =IFERROR(__xludf.DUMMYFUNCTION("FILTER(Dipromats!F$3:F$101, REGEXMATCH(Dipromats!$A$3:$A$101, ""(?i)"" & $A12), NOT(REGEXMATCH(Dipromats!$A$3:$A$101, ""(?i)complete"")) )"),0.578681917130575) -> 0.57868192 | F12: =IFERROR(__xludf.DUMMYFUNCTION("FILTER(Dipromats!G$3:G$101, REGEXMATCH(Dipromats!$A$3:$A$101, ""(?i)"" & $A12), NOT(REGEXMATCH(Dipromats!$A$3:$A$101, ""(?i)complete"")) )"),0.545763744390765) -> 0.54576374 | G12: =IFERROR(__xludf.DUMMYFUNCTION("FILTER(Dipromats!H$3:H$101, REGEXMATCH(Dipromats!$A$3:$A$101, ""(?i)"" & $A12), NOT(REGEXMATCH(Dipromats!$A$3:$A$101, ""(?i)complete"")) )"),0.524262991587101) -> 0.52426299 | H12: =IFERROR(__xludf.DUMMYFUNCTION("FILTER(Dipromats!I$3:I$101, REGEXMATCH(Dipromats!$A$3:$A$101, ""(?i)"" & $A12), NOT(REGEXMATCH(Dipromats!$A$3:$A$101, ""(?i)complete"")) )"),0.284838731621514) -> 0.28483873 | I12: =IFERROR(__xludf.DUMMYFUNCTION("FILTER(Dipromats!J$3:J$101, REGEXMATCH(Dipromats!$A$3:$A$101, ""(?i)"" & $A12), NOT(REGEXMATCH(Dipromats!$A$3:$A$101, ""(?i)complete"")) )"),0.300772443809359) -> 0.30077244 | M12: Enhanced Desc Only
A13: delta_gpt_description | B13: =B3-B12 -> -0.0058130462 | C13: =C3-C12 -> -0.030152336 | D13: =D3-D12 -> -0.0012039321 | E13: =E3-E12 -> -0.013987502 | F13: =F3-F12 -> 0.0061727703 | G13: =G3-G12 -> -0.025267994 | H13: =H3-H12 -> 0.048766415 | I13: =I3-I12 -> 0.066736391 | J13: =AVERAGE(B13:I13) -> 0.0056563456 | L13: Number of models better than no_no | O13: =COUNTIF(B7:I7,"<0") + COUNTIF(B9:I9,"<0") + COUNTIF(B11:I11,"<0") + COUNTIF(B13:I13,"<0") + COUNTIF(B15:I15,"<0") + COUNTIF(B17:I17,"<0") + COUNTIF(B26:I26,"<0") + COUNTIF(B28:I28,"<0") + COUNTIF(B30:I30,"<0") + COUNTIF(B32:I32,"<0") + COUNTIF(B34:I34,"<0") + COUNTIF(B36:I36,"<0") + COUNTIF(B45:I45,"<0") + COUNTIF(B47:I47,"<0") + COUNTIF(B49:I49,"<0") + COUNTIF(B51:I51,"<0") + COUNTIF(B53:I53,"<0") + COUNTIF(B55:I55,"<0") + COUNTIF(B64:I64,"<0") + COUNTIF(B66:I66,"<0") + COUNTIF(B68:I68,"<0") + COUNTIF(B69:I69,"<0") + COUNTIF(B70:I70,"<0") + COUNTIF(B72:I72,"<0") + COUNTIF(B74:I74,"<0") -> 32 | P13: 32 | Q13: 45 | R13: 19 | S13: 32 | T13: 32 | U13: =SUM(P13:T13) -> 160
A14: own_description_complete | B14: =IFERROR(__xludf.DUMMYFUNCTION("FILTER(Dipromats!C$3:C$101, REGEXMATCH(Dipromats!$A$3:$A$101, ""(?i)"" & $A14) )"),0.632355163340107) -> 0.63235516 | C14: =IFERROR(__xludf.DUMMYFUNCTION("FILTER(Dipromats!D$3:D$101, REGEXMATCH(Dipromats!$A$3:$A$101, ""(?i)"" & $A14) )"),0.606225827187698) -> 0.60622583 | D14: =IFERROR(__xludf.DUMMYFUNCTION("FILTER(Dipromats!E$3:E$101, REGEXMATCH(Dipromats!$A$3:$A$101, ""(?i)"" & $A14) )"),0.535090217689681) -> 0.53509022 | E14: =IFERROR(__xludf.DUMMYFUNCTION("FILTER(Dipromats!F$3:F$101, REGEXMATCH(Dipromats!$A$3:$A$101, ""(?i)"" & $A14) )"),0.477750371254548) -> 0.47775037 | F14: =IFERROR(__xludf.DUMMYFUNCTION("FILTER(Dipromats!G$3:G$101, REGEXMATCH(Dipromats!$A$3:$A$101, ""(?i)"" & $A14) )"),0.457442229094388) -> 0.45744223 | G14: =IFERROR(__xludf.DUMMYFUNCTION("FILTER(Dipromats!H$3:H$101, REGEXMATCH(Dipromats!$A$3:$A$101, ""(?i)"" & $A14) )"),0.427462251024684) -> 0.42746225 | H14: =IFERROR(__xludf.DUMMYFUNCTION("FILTER(Dipromats!I$3:I$101, REGEXMATCH(Dipromats!$A$3:$A$101, ""(?i)"" & $A14) )"),0.245367655632764) -> 0.24536766 | I14: =IFERROR(__xludf.DUMMYFUNCTION("FILTER(Dipromats!J$3:J$101, REGEXMATCH(Dipromats!$A$3:$A$101, ""(?i)"" & $A14) )"),0.282654794342775) -> 0.28265479 | L14: Number of models worse than no_no | O14: =COUNTIF(B7:I7,">0") + COUNTIF(B9:I9,">0") + COUNTIF(B11:I11,">0") + COUNTIF(B13:I13,">0") + COUNTIF(B15:I15,">0") + COUNTIF(B17:I17,">0") + COUNTIF(B26:I26,">0") + COUNTIF(B28:I28,">0") + COUNTIF(B30:I30,">0") + COUNTIF(B32:I32,">0") + COUNTIF(B34:I34,">0") + COUNTIF(B36:I36,">0") + COUNTIF(B45:I45,">0") + COUNTIF(B47:I47,">0") + COUNTIF(B49:I49,">0") + COUNTIF(B51:I51,">0") + COUNTIF(B53:I53,">0") + COUNTIF(B55:I55,">0") + COUNTIF(B64:I64,">0") + COUNTIF(B66:I66,">0") + COUNTIF(B68:I68,">0") + COUNTIF(B69:I69,">0") + COUNTIF(B70:I70,">0") + COUNTIF(B72:I72,">0") + COUNTIF(B74:I74,">0") -> 146 | P14: 148 | Q14: 133 | R14: 159 | S14: 146 | T14: 146 | U14: =SUM(P14:T14) -> 732
A15: delta_own_description_comp | B15: =B3-B14 -> 0.0021494519 | C15: =C3-C14 -> -0.022831507 | D15: =D3-D14 -> 0.07745669 | E15: =E3-E14 -> 0.086944043 | F15: =F3-F14 -> 0.094494286 | G15: =G3-G14 -> 0.071532746 | H15: =H3-H14 -> 0.088237491 | I15: =I3-I14 -> 0.08485404 | J15: =AVERAGE(B15:I15) -> 0.060354655 | L15: Percentage of better models | O15: =(O13*100)/(O13+O14) -> 17.977528 | U15: =(U13*100)/(U13+U14) -> 17.93722
A16: gpt_description_complete | B16: =IFERROR(__xludf.DUMMYFUNCTION("FILTER(Dipromats!C$3:C$101, REGEXMATCH(Dipromats!$A$3:$A$101, ""(?i)"" & $A16) )"),0.626620634285161) -> 0.62662063 | C16: =IFERROR(__xludf.DUMMYFUNCTION("FILTER(Dipromats!D$3:D$101, REGEXMATCH(Dipromats!$A$3:$A$101, ""(?i)"" & $A16) )"),0.604801060798369) -> 0.60480106 | D16: =IFERROR(__xludf.DUMMYFUNCTION("FILTER(Dipromats!E$3:E$101, REGEXMATCH(Dipromats!$A$3:$A$101, ""(?i)"" & $A16) )"),0.274748595417237) -> 0.2747486 | E16: =IFERROR(__xludf.DUMMYFUNCTION("FILTER(Dipromats!F$3:F$101, REGEXMATCH(Dipromats!$A$3:$A$101, ""(?i)"" & $A16) )"),0.380177808740426) -> 0.38017781 | F16: =IFERROR(__xludf.DUMMYFUNCTION("FILTER(Dipromats!G$3:G$101, REGEXMATCH(Dipromats!$A$3:$A$101, ""(?i)"" & $A16) )"),0.484593915089339) -> 0.48459392 | G16: =IFERROR(__xludf.DUMMYFUNCTION("FILTER(Dipromats!H$3:H$101, REGEXMATCH(Dipromats!$A$3:$A$101, ""(?i)"" & $A16) )"),0.437797137788191) -> 0.43779714 | H16: =IFERROR(__xludf.DUMMYFUNCTION("FILTER(Dipromats!I$3:I$101, REGEXMATCH(Dipromats!$A$3:$A$101, ""(?i)"" & $A16) )"),0.220620940157727) -> 0.22062094 | I16: =IFERROR(__xludf.DUMMYFUNCTION("FILTER(Dipromats!J$3:J$101, REGEXMATCH(Dipromats!$A$3:$A$101, ""(?i)"" & $A16) )"),0.271705614091627) -> 0.27170561 | L16: Percentage of worst models | O16: =100-O15 -> 82.022472 | U16: =100-U15 -> 82.06278
A17: delta_gpt_description_comp | B17: =B3-B16 -> 0.007883981 | C17: =C3-C16 -> -0.021406741 | D17: =D3-D16 -> 0.33779831 | E17: =E3-E16 -> 0.18451661 | F17: =F3-F16 -> 0.0673426 | G17: =G3-G16 -> 0.06119786 | H17: =H3-H16 -> 0.11298421 | I17: =I3-I16 -> 0.095803221 | J17: =AVERAGE(B17:I17) -> 0.10576501
B18: =AVERAGE(B5,B7,B9,B11,B13,B15,B17) -> 0.0060365386 | C18: =AVERAGE(C5,C7,C9,C11,C13,C15,C17) -> -0.015654013 | D18: =AVERAGE(D5,D7,D9,D11,D13,D15,D17) -> 0.070498216 | E18: =AVERAGE(E5,E7,E9,E11,E13,E15,E17) -> 0.042592143 | F18: =AVERAGE(F5,F7,F9,F11,F13,F15,F17) -> 0.032280863 | G18: =AVERAGE(G5,G7,G9,G11,G13,G15,G17) -> 0.011747597 | H18: =AVERAGE(H5,H7,H9,H11,H13,H15,H17) -> 0.058117953 | I18: =AVERAGE(I5,I7,I9,I11,I13,I15,I17) -> 0.062730138
B19: =AVERAGE(B18,C18) -> -0.0048087372 | D19: =AVERAGE(D18,E18) -> 0.05654518 | F19: =AVERAGE(F18,G18) -> 0.02201423 | H19: =AVERAGE(H18,I18) -> 0.060424045
A21: 3_steps | B21: calme | D21: gemma | F21: exaone | H21: granite
A22: no_no | B22: =IFERROR(__xludf.DUMMYFUNCTION("FILTER(SemEval_2025_T2!$G$3:$G$132, REGEXMATCH(SemEval_2025_T2!$A$3:$A$132, ""(?i)"" & $B$21 &""_"" & $A22) )"),0.469629994858942) -> 0.46962999 | C22: =IFERROR(__xludf.DUMMYFUNCTION("FILTER(SemEval_2025_T2!$H$3:$H$132, REGEXMATCH(SemEval_2025_T2!$A$3:$A$132, ""(?i)"" & $B$21 &""_"" & $A22) )"),0.29768447503913) -> 0.29768448 | D22: =IFERROR(__xludf.DUMMYFUNCTION("FILTER(SemEval_2025_T2!$G$3:$G$132, REGEXMATCH(SemEval_2025_T2!$A$3:$A$132, ""(?i)"" & $D$21 &""_"" & $A22) )"),0.386661612184486) -> 0.38666161 | E22: =IFERROR(__xludf.DUMMYFUNCTION("FILTER(SemEval_2025_T2!$H$3:$H$132, REGEXMATCH(SemEval_2025_T2!$A$3:$A$132, ""(?i)"" & $D$21 &""_"" & $A22) )"),0.200154216124963) -> 0.20015422 | F22: =IFERROR(__xludf.DUMMYFUNCTION("FILTER(SemEval_2025_T2!$G$3:$G$132, REGEXMATCH(SemEval_2025_T2!$A$3:$A$132, ""(?i)"" & $F$21 &""_"" & $A22) )"),0.322135984191247) -> 0.32213598 | G22: =IFERROR(__xludf.DUMMYFUNCTION("FILTER(SemEval_2025_T2!$H$3:$H$132, REGEXMATCH(SemEval_2025_T2!$A$3:$A$132, ""(?i)"" & $F$21 &""_"" & $A22) )"),0.15832344209996) -> 0.15832344 | H22: =IFERROR(__xludf.DUMMYFUNCTION("FILTER(SemEval_2025_T2!$G$3:$G$132, REGEXMATCH(SemEval_2025_T2!$A$3:$A$132, ""(?i)"" & $H$21 &""_"" & $A22) )"),0.207104738828423) -> 0.20710474 | I22: =IFERROR(__xludf.DUMMYFUNCTION("FILTER(SemEval_2025_T2!$H$3:$H$132, REGEXMATCH(SemEval_2025_T2!$A$3:$A$132, ""(?i)"" & $H$21 &""_"" & $A22) )"),0.087871224883977) -> 0.087871225
A23: original_original | B23: =IFERROR(__xludf.DUMMYFUNCTION("FILTER(SemEval_2025_T2!$G$3:$G$132, REGEXMATCH(SemEval_2025_T2!$A$3:$A$132, ""(?i)"" & $B$21 &""_"" & $A23) )"),0.514035206022048) -> 0.51403521 | C23: =IFERROR(__xludf.DUMMYFUNCTION("FILTER(SemEval_2025_T2!$H$3:$H$132, REGEXMATCH(SemEval_2025_T2!$A$3:$A$132, ""(?i)"" & $B$21 &""_"" & $A23) )"),0.307645133386631) -> 0.30764513 | D23: =IFERROR(__xludf.DUMMYFUNCTION("FILTER(SemEval_2025_T2!$G$3:$G$132, REGEXMATCH(SemEval_2025_T2!$A$3:$A$132, ""(?i)"" & $D$21 &""_"" & $A23) )"),0.381269392078906) -> 0.38126939 | E23: =IFERROR(__xludf.DUMMYFUNCTION("FILTER(SemEval_2025_T2!$H$3:$H$132, REGEXMATCH(SemEval_2025_T2!$A$3:$A$132, ""(?i)"" & $D$21 &""_"" & $A23) )"),0.213641884382488) -> 0.21364188 | F23: =IFERROR(__xludf.DUMMYFUNCTION("FILTER(SemEval_2025_T2!$G$3:$G$132, REGEXMATCH(SemEval_2025_T2!$A$3:$A$132, ""(?i)"" & $F$21 &""_"" & $A23) )"),0.297130229419703) -> 0.29713023 | G23: =IFERROR(__xludf.DUMMYFUNCTION("FILTER(SemEval_2025_T2!$H$3:$H$132, REGEXMATCH(SemEval_2025_T2!$A$3:$A$132, ""(?i)"" & $F$21 &""_"" & $A23) )"),0.118694163326551) -> 0.11869416 | H23: =IFERROR(__xludf.DUMMYFUNCTION("FILTER(SemEval_2025_T2!$G$3:$G$132, REGEXMATCH(SemEval_2025_T2!$A$3:$A$132, ""(?i)"" & $H$21 &""_"" & $A23) )"),0.238378224888286) -> 0.23837822 | I23: =IFERROR(__xludf.DUMMYFUNCTION("FILTER(SemEval_2025_T2!$H$3:$H$132, REGEXMATCH(SemEval_2025_T2!$A$3:$A$132, ""(?i)"" & $H$21 &""_"" & $A23) )"),0.083454375288068) -> 0.083454375 | P23: EN | Q23: HI | R23: PT | S23: BG | T23: RU | U23: Total
A24: delta_original | B24: =B22-B23 -> -0.044405211 | C24: =C22-C23 -> -0.0099606583 | D24: =D22-D23 -> 0.0053922201 | E24: =E22-E23 -> -0.013487668 | F24: =F22-F23 -> 0.025005755 | G24: =G22-G23 -> 0.039629279 | H24: =H22-H23 -> -0.031273486 | I24: =I22-I23 -> 0.0044168496 | J24: =AVERAGE(B24,D24,F24,H24) -> -0.011320181 | K24: =AVERAGE(C24,E24,G24,I24) -> 0.0051494504 | L24: =AVERAGE(J24,K24) -> -0.0030853651 | N24: delta_original | O24: =AVERAGE(L24,L43,L62) -> 0.0070479367 | P24: -0.0069816786 | Q24: -0.003066861 | R24: 0.011016103 | S24: -0.0024110006 | T24: 0.0070479367 | U24: =AVERAGE(P24:T24) -> 0.0011209
A25: only_title | B25: =IFERROR(__xludf.DUMMYFUNCTION("FILTER(SemEval_2025_T2!$G$3:$G$132, REGEXMATCH(SemEval_2025_T2!$A$3:$A$132, ""(?i)"" & $B$21 &""_"" & $A25) )"),0.443146947744113) -> 0.44314695 | C25: =IFERROR(__xludf.DUMMYFUNCTION("FILTER(SemEval_2025_T2!$H$3:$H$132, REGEXMATCH(SemEval_2025_T2!$A$3:$A$132, ""(?i)"" & $B$21 &""_"" & $A25) )"),0.278619253553464) -> 0.27861925 | D25: =IFERROR(__xludf.DUMMYFUNCTION("FILTER(SemEval_2025_T2!$G$3:$G$132, REGEXMATCH(SemEval_2025_T2!$A$3:$A$132, ""(?i)"" & $D$21 &""_"" & $A25) )"),0.183951176893282) -> 0.18395118 | E25: =IFERROR(__xludf.DUMMYFUNCTION("FILTER(SemEval_2025_T2!$H$3:$H$132, REGEXMATCH(SemEval_2025_T2!$A$3:$A$132, ""(?i)"" & $D$21 &""_"" & $A25) )"),0.076478375942546) -> 0.076478376 | F25: =IFERROR(__xludf.DUMMYFUNCTION("FILTER(SemEval_2025_T2!$G$3:$G$132, REGEXMATCH(SemEval_2025_T2!$A$3:$A$132, ""(?i)"" & $F$21 &""_"" & $A25) )"),0.322483844225949) -> 0.32248384 | G25: =IFERROR(__xludf.DUMMYFUNCTION("FILTER(SemEval_2025_T2!$H$3:$H$132, REGEXMATCH(SemEval_2025_T2!$A$3:$A$132, ""(?i)"" & $F$21 &""_"" & $A25) )"),0.137031714619164) -> 0.13703171 | H25: =IFERROR(__xludf.DUMMYFUNCTION("FILTER(SemEval_2025_T2!$G$3:$G$132, REGEXMATCH(SemEval_2025_T2!$A$3:$A$132, ""(?i)"" & $H$21 &""_"" & $A25) )"),0.159618888713625) -> 0.15961889 | I25: =IFERROR(__xludf.DUMMYFUNCTION("FILTER(SemEval_2025_T2!$H$3:$H$132, REGEXMATCH(SemEval_2025_T2!$A$3:$A$132, ""(?i)"" & $H$21 &""_"" & $A25) )"),0.051741760021139) -> 0.05174176 | N25: delta_own_title | O25: =AVERAGE(L26,L45,L64) -> 0.030769893 | P25: 0.032023262 | Q25: 0.016310077 | R25: 0.05698846 | S25: 0.036312655 | T25: 0.030769893 | U25: =AVERAGE(P25:T25) -> 0.034480869
A26: delta_own_title | B26: =B22-B25 -> 0.026483047 | C26: =C22-C25 -> 0.019065221 | D26: =D22-D25 -> 0.20271044 | E26: =E22-E25 -> 0.12367584 | F26: =F22-F25 -> -0.00034786003 | G26: =G22-G25 -> 0.021291727 | H26: =H22-H25 -> 0.04748585 | I26: =I22-I25 -> 0.036129465 | J26: =AVERAGE(B26,D26,F26,H26) -> 0.069082868 | K26: =AVERAGE(C26,E26,G26,I26) -> 0.050040564 | L26: =AVERAGE(J26,K26) -> 0.059561716 | N26: delta_gpt_title | O26: =AVERAGE(L28,L47,L66) -> 0.032219721 | P26: 0.030532007 | Q26: 0.016634236 | R26: 0.062613484 | S26: 0.037876003 | T26: 0.032219721 | U26: =AVERAGE(P26:T26) -> 0.03597509
A27: zero_shot_gpt_only_title | B27: =IFERROR(__xludf.DUMMYFUNCTION("FILTER(SemEval_2025_T2!$G$3:$G$132, REGEXMATCH(SemEval_2025_T2!$A$3:$A$132, ""(?i)"" & $B$21 &""_"" & $A27) )"),0.413172598162071) -> 0.4131726 | C27: =IFERROR(__xludf.DUMMYFUNCTION("FILTER(SemEval_2025_T2!$H$3:$H$132, REGEXMATCH(SemEval_2025_T2!$A$3:$A$132, ""(?i)"" & $B$21 &""_"" & $A27) )"),0.238469869626549) -> 0.23846987 | D27: =IFERROR(__xludf.DUMMYFUNCTION("FILTER(SemEval_2025_T2!$G$3:$G$132, REGEXMATCH(SemEval_2025_T2!$A$3:$A$132, ""(?i)"" & $D$21 &""_"" & $A27) )"),0.201656347341367) -> 0.20165635 | E27: =IFERROR(__xludf.DUMMYFUNCTION("FILTER(SemEval_2025_T2!$H$3:$H$132, REGEXMATCH(SemEval_2025_T2!$A$3:$A$132, ""(?i)"" & $D$21 &""_"" & $A27) )"),0.098389118476481) -> 0.098389118 | F27: =IFERROR(__xludf.DUMMYFUNCTION("FILTER(SemEval_2025_T2!$G$3:$G$132, REGEXMATCH(SemEval_2025_T2!$A$3:$A$132, ""(?i)"" & $F$21 &""_"" & $A27) )"),0.266104055009318) -> 0.26610406 | G27: =IFERROR(__xludf.DUMMYFUNCTION("FILTER(SemEval_2025_T2!$H$3:$H$132, REGEXMATCH(SemEval_2025_T2!$A$3:$A$132, ""(?i)"" & $F$21 &""_"" & $A27) )"),0.099810456390213) -> 0.099810456 | H27: =IFERROR(__xludf.DUMMYFUNCTION("FILTER(SemEval_2025_T2!$G$3:$G$132, REGEXMATCH(SemEval_2025_T2!$A$3:$A$132, ""(?i)"" & $H$21 &""_"" & $A27) )"),0.246870696554907) -> 0.2468707 | I27: =IFERROR(__xludf.DUMMYFUNCTION("FILTER(SemEval_2025_T2!$H$3:$H$132, REGEXMATCH(SemEval_2025_T2!$A$3:$A$132, ""(?i)"" & $H$21 &""_"" & $A27) )"),0.059954252922066) -> 0.059954253 | N27: delta_own_description | O27: =AVERAGE(L30,L49,L68) -> 0.022891151 | P27: 0.015066301 | Q27: 0.013764556 | R27: 0.057258518 | S27: 0.030038515 | T27: 0.022891151 | U27: =AVERAGE(P27:T27) -> 0.027803808
A28: delta_gpt_title | B28: =B22-B27 -> 0.056457397 | C28: =C22-C27 -> 0.059214605 | D28: =D22-D27 -> 0.18500526 | E28: =E22-E27 -> 0.1017651 | F28: =F22-F27 -> 0.056031929 | G28: =G22-G27 -> 0.058512986 | H28: =H22-H27 -> -0.039765958 | I28: =I22-I27 -> 0.027916972 | J28: =AVERAGE(B28,D28,F28,H28) -> 0.064432158 | K28: =AVERAGE(C28,E28,G28,I28) -> 0.061852415 | L28: =AVERAGE(J28,K28) -> 0.063142287 | N28: delta_gpt_description | O28: =AVERAGE(L32,L51,L70) -> 0.034600433 | P28: 0.018968957 | Q28: 0.012814573 | R28: 0.044861832 | S28: 0.030064454 | T28: 0.034600433 | U28: =AVERAGE(P28:T28) -> 0.02826205
A29: title_description | B29: =IFERROR(__xludf.DUMMYFUNCTION("FILTER(SemEval_2025_T2!$G$3:$G$132, REGEXMATCH(SemEval_2025_T2!$A$3:$A$132, ""(?i)"" & $B$21 &""_"" & $A29), NOT(REGEXMATCH(SemEval_2025_T2!$A$3:$A$132, ""(?i)complete"")) )"),0.475694995063416) -> 0.475695 | C29: =IFERROR(__xludf.DUMMYFUNCTION("FILTER(SemEval_2025_T2!$H$3:$H$132, REGEXMATCH(SemEval_2025_T2!$A$3:$A$132, ""(?i)"" & $B$21 &""_"" & $A29), NOT(REGEXMATCH(SemEval_2025_T2!$A$3:$A$132, ""(?i)complete"")) )"),0.255848749114133) -> 0.25584875 | D29: =IFERROR(__xludf.DUMMYFUNCTION("FILTER(SemEval_2025_T2!$G$3:$G$132, REGEXMATCH(SemEval_2025_T2!$A$3:$A$132, ""(?i)"" & $D$21 &""_"" & $A29), NOT(REGEXMATCH(SemEval_2025_T2!$A$3:$A$132, ""(?i)complete"")) )"),0.263223865900181) -> 0.26322387 | E29: =IFERROR(__xludf.DUMMYFUNCTION("FILTER(SemEval_2025_T2!$H$3:$H$132, REGEXMATCH(SemEval_2025_T2!$A$3:$A$132, ""(?i)"" & $D$21 &""_"" & $A29), NOT(REGEXMATCH(SemEval_2025_T2!$A$3:$A$132, ""(?i)complete"")) )"),0.12963188756561) -> 0.12963189 | F29: =IFERROR(__xludf.DUMMYFUNCTION("FILTER(SemEval_2025_T2!$G$3:$G$132, REGEXMATCH(SemEval_2025_T2!$A$3:$A$132, ""(?i)"" & $F$21 &""_"" & $A29), NOT(REGEXMATCH(SemEval_2025_T2!$A$3:$A$132, ""(?i)complete"")) )"),0.301315471370734) -> 0.30131547 | G29: =IFERROR(__xludf.DUMMYFUNCTION("FILTER(SemEval_2025_T2!$H$3:$H$132, REGEXMATCH(SemEval_2025_T2!$A$3:$A$132, ""(?i)"" & $F$21 &""_"" & $A29), NOT(REGEXMATCH(SemEval_2025_T2!$A$3:$A$132, ""(?i)complete"")) )"),0.111016939313498) -> 0.11101694 | H29: =IFERROR(__xludf.DUMMYFUNCTION("FILTER(SemEval_2025_T2!$G$3:$G$132, REGEXMATCH(SemEval_2025_T2!$A$3:$A$132, ""(?i)"" & $H$21 &""_"" & $A29), NOT(REGEXMATCH(SemEval_2025_T2!$A$3:$A$132, ""(?i)complete"")) )"),0.236880045685308) -> 0.23688005 | I29: =IFERROR(__xludf.DUMMYFUNCTION("FILTER(SemEval_2025_T2!$H$3:$H$132, REGEXMATCH(SemEval_2025_T2!$A$3:$A$132, ""(?i)"" & $H$21 &""_"" & $A29), NOT(REGEXMATCH(SemEval_2025_T2!$A$3:$A$132, ""(?i)complete"")) )"),0.068547640773795) -> 0.068547641 | N29: delta_own_description_comp | O29: =AVERAGE(L34,L53,L72) -> 0.070568225 | P29: 0.041426009 | Q29: 0.036561734 | R29: 0.1095161 | S29: 0.062328362 | T29: 0.070568225 | U29: =AVERAGE(P29:T29) -> 0.064080086
A30: delta_own_description | B30: =B22-B29 -> -0.0060650002 | C30: =C22-C29 -> 0.041835726 | D30: =D22-D29 -> 0.12343775 | E30: =E22-E29 -> 0.070522329 | F30: =F22-F29 -> 0.020820513 | G30: =G22-G29 -> 0.047306503 | H30: =H22-H29 -> -0.029775307 | I30: =I22-I29 -> 0.019323584 | J30: =AVERAGE(B30,D30,F30,H30) -> 0.027104488 | K30: =AVERAGE(C30,E30,G30,I30) -> 0.044747035 | L30: =AVERAGE(J30,K30) -> 0.035925762 | N30: delta_gpt_description_comp | O30: =AVERAGE(L36,L55,L74) -> 0.057564 | P30: 0.036203006 | Q30: 0.01918181 | R30: 0.074347978 | S30: 0.039062342 | T30: 0.057564 | U30: =AVERAGE(P30:T30) -> 0.045271827
A31: zero_shot_gpt_title_description | B31: =IFERROR(__xludf.DUMMYFUNCTION("FILTER(SemEval_2025_T2!$G$3:$G$132, REGEXMATCH(SemEval_2025_T2!$A$3:$A$132, ""(?i)"" & $B$21 &""_"" & $A31), NOT(REGEXMATCH(SemEval_2025_T2!$A$3:$A$132, ""(?i)complete"")) )"),0.447556318827371) -> 0.44755632 | C31: =IFERROR(__xludf.DUMMYFUNCTION("FILTER(SemEval_2025_T2!$H$3:$H$132, REGEXMATCH(SemEval_2025_T2!$A$3:$A$132, ""(?i)"" & $B$21 &""_"" & $A31), NOT(REGEXMATCH(SemEval_2025_T2!$A$3:$A$132, ""(?i)complete"")) )"),0.260569443848998) -> 0.26056944 | D31: =IFERROR(__xludf.DUMMYFUNCTION("FILTER(SemEval_2025_T2!$G$3:$G$132, REGEXMATCH(SemEval_2025_T2!$A$3:$A$132, ""(?i)"" & $D$21 &""_"" & $A31), NOT(REGEXMATCH(SemEval_2025_T2!$A$3:$A$132, ""(?i)complete"")) )"),0.214114112495691) -> 0.21411411 | E31: =IFERROR(__xludf.DUMMYFUNCTION("FILTER(SemEval_2025_T2!$H$3:$H$132, REGEXMATCH(SemEval_2025_T2!$A$3:$A$132, ""(?i)"" & $D$21 &""_"" & $A31), NOT(REGEXMATCH(SemEval_2025_T2!$A$3:$A$132, ""(?i)complete"")) )"),0.106058068538986) -> 0.10605807 | F31: =IFERROR(__xludf.DUMMYFUNCTION("FILTER(SemEval_2025_T2!$G$3:$G$132, REGEXMATCH(SemEval_2025_T2!$A$3:$A$132, ""(?i)"" & $F$21 &""_"" & $A31), NOT(REGEXMATCH(SemEval_2025_T2!$A$3:$A$132, ""(?i)complete"")) )"),0.283892118115802) -> 0.28389212 | G31: =IFERROR(__xludf.DUMMYFUNCTION("FILTER(SemEval_2025_T2!$H$3:$H$132, REGEXMATCH(SemEval_2025_T2!$A$3:$A$132, ""(?i)"" & $F$21 &""_"" & $A31), NOT(REGEXMATCH(SemEval_2025_T2!$A$3:$A$132, ""(?i)complete"")) )"),0.113968810788851) -> 0.11396881 | H31: =IFERROR(__xludf.DUMMYFUNCTION("FILTER(SemEval_2025_T2!$G$3:$G$132, REGEXMATCH(SemEval_2025_T2!$A$3:$A$132, ""(?i)"" & $H$21 &""_"" & $A31), NOT(REGEXMATCH(SemEval_2025_T2!$A$3:$A$132, ""(?i)complete"")) )"),0.212448441324757) -> 0.21244844 | I31: =IFERROR(__xludf.DUMMYFUNCTION("FILTER(SemEval_2025_T2!$H$3:$H$132, REGEXMATCH(SemEval_2025_T2!$A$3:$A$132, ""(?i)"" & $H$21 &""_"" & $A31), NOT(REGEXMATCH(SemEval_2025_T2!$A$3:$A$132, ""(?i)complete"")) )"),0.062289598997493) -> 0.062289599
A32: delta_gpt_description | B32: =B22-B31 -> 0.022073676 | C32: =C22-C31 -> 0.037115031 | D32: =D22-D31 -> 0.1725475 | E32: =E22-E31 -> 0.094096148 | F32: =F22-F31 -> 0.038243866 | G32: =G22-G31 -> 0.044354631 | H32: =H22-H31 -> -0.0053437025 | I32: =I22-I31 -> 0.025581626 | J32: =AVERAGE(B32,D32,F32,H32) -> 0.056880335 | K32: =AVERAGE(C32,E32,G32,I32) -> 0.050286859 | L32: =AVERAGE(J32,K32) -> 0.053583597
A33: title_description_complete | B33: =IFERROR(__xludf.DUMMYFUNCTION("FILTER(SemEval_2025_T2!$G$3:$G$132, REGEXMATCH(SemEval_2025_T2!$A$3:$A$132, ""(?i)"" & $B$21 &""_"" & $A33) )"),0.430385701433069) -> 0.4303857 | C33: =IFERROR(__xludf.DUMMYFUNCTION("FILTER(SemEval_2025_T2!$H$3:$H$132, REGEXMATCH(SemEval_2025_T2!$A$3:$A$132, ""(?i)"" & $B$21 &""_"" & $A33) )"),0.246254129631052) -> 0.24625413 | D33: =IFERROR(__xludf.DUMMYFUNCTION("FILTER(SemEval_2025_T2!$G$3:$G$132, REGEXMATCH(SemEval_2025_T2!$A$3:$A$132, ""(?i)"" & $D$21 &""_"" & $A33) )"),0.031951417004048) -> 0.031951417 | E33: =IFERROR(__xludf.DUMMYFUNCTION("FILTER(SemEval_2025_T2!$H$3:$H$132, REGEXMATCH(SemEval_2025_T2!$A$3:$A$132, ""(?i)"" & $D$21 &""_"" & $A33) )"),0.016105263157894) -> 0.016105263 | F33: =IFERROR(__xludf.DUMMYFUNCTION("FILTER(SemEval_2025_T2!$G$3:$G$132, REGEXMATCH(SemEval_2025_T2!$A$3:$A$132, ""(?i)"" & $F$21 &""_"" & $A33) )"),0.288692243429085) -> 0.28869224 | G33: =IFERROR(__xludf.DUMMYFUNCTION("FILTER(SemEval_2025_T2!$H$3:$H$132, REGEXMATCH(SemEval_2025_T2!$A$3:$A$132, ""(?i)"" & $F$21 &""_"" & $A33) )"),0.125237610500161) -> 0.12523761 | H33: =IFERROR(__xludf.DUMMYFUNCTION("FILTER(SemEval_2025_T2!$G$3:$G$132, REGEXMATCH(SemEval_2025_T2!$A$3:$A$132, ""(?i)"" & $H$21 &""_"" & $A33) )"),0.160590853882959) -> 0.16059085 | I33: =IFERROR(__xludf.DUMMYFUNCTION("FILTER(SemEval_2025_T2!$H$3:$H$132, REGEXMATCH(SemEval_2025_T2!$A$3:$A$132, ""(?i)"" & $H$21 &""_"" & $A33) )"),0.059550146974033) -> 0.059550147
A34: delta_own_description_comp | B34: =B22-B33 -> 0.039244293 | C34: =C22-C33 -> 0.051430345 | D34: =D22-D33 -> 0.3547102 | E34: =E22-E33 -> 0.18404895 | F34: =F22-F33 -> 0.033443741 | G34: =G22-G33 -> 0.033085832 | H34: =H22-H33 -> 0.046513885 | I34: =I22-I33 -> 0.028321078 | J34: =AVERAGE(B34,D34,F34,H34) -> 0.11847803 | K34: =AVERAGE(C34,E34,G34,I34) -> 0.074221552 | L34: =AVERAGE(J34,K34) -> 0.09634979
A35: zero_shot_gpt_title_description_complete | B35: =IFERROR(__xludf.DUMMYFUNCTION("FILTER(SemEval_2025_T2!$G$3:$G$132, REGEXMATCH(SemEval_2025_T2!$A$3:$A$132, ""(?i)"" & $B$21 &""_"" & $A35) )"),0.387901176016965) -> 0.38790118 | C35: =IFERROR(__xludf.DUMMYFUNCTION("FILTER(SemEval_2025_T2!$H$3:$H$132, REGEXMATCH(SemEval_2025_T2!$A$3:$A$132, ""(?i)"" & $B$21 &""_"" & $A35) )"),0.233524755451476) -> 0.23352476 | D35: =IFERROR(__xludf.DUMMYFUNCTION("FILTER(SemEval_2025_T2!$G$3:$G$132, REGEXMATCH(SemEval_2025_T2!$A$3:$A$132, ""(?i)"" & $D$21 &""_"" & $A35) )"),0.190261348592927) -> 0.19026135 | E35: =IFERROR(__xludf.DUMMYFUNCTION("FILTER(SemEval_2025_T2!$H$3:$H$132, REGEXMATCH(SemEval_2025_T2!$A$3:$A$132, ""(?i)"" & $D$21 &""_"" & $A35) )"),0.088050555691827) -> 0.088050556 | F35: =IFERROR(__xludf.DUMMYFUNCTION("FILTER(SemEval_2025_T2!$G$3:$G$132, REGEXMATCH(SemEval_2025_T2!$A$3:$A$132, ""(?i)"" & $F$21 &""_"" & $A35) )"),0.259401876486087) -> 0.25940188 | G35: =IFERROR(__xludf.DUMMYFUNCTION("FILTER(SemEval_2025_T2!$H$3:$H$132, REGEXMATCH(SemEval_2025_T2!$A$3:$A$132, ""(?i)"" & $F$21 &""_"" & $A35) )"),0.116199203293332) -> 0.1161992 | H35: =IFERROR(__xludf.DUMMYFUNCTION("FILTER(SemEval_2025_T2!$G$3:$G$132, REGEXMATCH(SemEval_2025_T2!$A$3:$A$132, ""(?i)"" & $H$21 &""_"" & $A35) )"),0.192691655712708) -> 0.19269166 | I35: =IFERROR(__xludf.DUMMYFUNCTION("FILTER(SemEval_2025_T2!$H$3:$H$132, REGEXMATCH(SemEval_2025_T2!$A$3:$A$132, ""(?i)"" & $H$21 &""_"" & $A35) )"),0.035547496655391) -> 0.035547497
A36: delta_gpt_description_comp | B36: =B22-B35 -> 0.081728819 | C36: =C22-C35 -> 0.06415972 | D36: =D22-D35 -> 0.19640026 | E36: =E22-E35 -> 0.11210366 | F36: =F22-F35 -> 0.062734108 | G36: =G22-G35 -> 0.042124239 | H36: =H22-H35 -> 0.014413083 | I36: =I22-I35 -> 0.052323728 | J36: =AVERAGE(B36,D36,F36,H36) -> 0.088819068 | K36: =AVERAGE(C36,E36,G36,I36) -> 0.067677837 | L36: =AVERAGE(J36,K36) -> 0.078248453
B37: =AVERAGE(B24,B26,B28,B30,B32,B34,B36) -> 0.02507386 | C37: =AVERAGE(C24,C26,C28,C30,C32,C34,C36) -> 0.037551427 | D37: =AVERAGE(D24,D26,D28,D30,D32,D34,D36) -> 0.17717195 | E37: =AVERAGE(E24,E26,E28,E30,E32,E34,E36) -> 0.09610348 | F37: =AVERAGE(F24,F26,F28,F30,F32,F34,F36) -> 0.033704579 | G37: =AVERAGE(G24,G26,G28,G30,G32,G34,G36) -> 0.040900742 | H37: =AVERAGE(H24,H26,H28,H30,H32,H34,H36) -> 0.00032205215 | I37: =AVERAGE(I24,I26,I28,I30,I32,I34,I36) -> 0.027716186
B38: =AVERAGE(B37,C37) -> 0.031312644 | D38: =AVERAGE(D37,E37) -> 0.13663771 | F38: =AVERAGE(F37,G37) -> 0.037302661 | H38: =AVERAGE(H37,I37) -> 0.014019119
A40: hybrid | B40: calme | D40: gemma | F40: exaone | H40: granite
A41: no_no | B41: =IFERROR(__xludf.DUMMYFUNCTION("FILTER(SemEval_2025_T2!$E$3:$E$132, REGEXMATCH(SemEval_2025_T2!$A$3:$A$132, ""(?i)"" & $B$21 &""_"" & $A41) )"),0.538777572135467) -> 0.53877757 | C41: =IFERROR(__xludf.DUMMYFUNCTION("FILTER(SemEval_2025_T2!$F$3:$F$132, REGEXMATCH(SemEval_2025_T2!$A$3:$A$132, ""(?i)"" & $B$21 &""_"" & $A41) )"),0.339727953333216) -> 0.33972795 | D41: =IFERROR(__xludf.DUMMYFUNCTION("FILTER(SemEval_2025_T2!$E$3:$E$132, REGEXMATCH(SemEval_2025_T2!$A$3:$A$132, ""(?i)"" & $D$21 &""_"" & $A41) )"),0.17067633506844) -> 0.17067634 | E41: =IFERROR(__xludf.DUMMYFUNCTION("FILTER(SemEval_2025_T2!$F$3:$F$132, REGEXMATCH(SemEval_2025_T2!$A$3:$A$132, ""(?i)"" & $D$21 &""_"" & $A41) )"),0.087106689801426) -> 0.08710669 | F41: =IFERROR(__xludf.DUMMYFUNCTION("FILTER(SemEval_2025_T2!$E$3:$E$132, REGEXMATCH(SemEval_2025_T2!$A$3:$A$132, ""(?i)"" & $F$21 &""_"" & $A41) )"),0.357943207377417) -> 0.35794321 | G41: =IFERROR(__xludf.DUMMYFUNCTION("FILTER(SemEval_2025_T2!$F$3:$F$132, REGEXMATCH(SemEval_2025_T2!$A$3:$A$132, ""(?i)"" & $F$21 &""_"" & $A41) )"),0.106532844056528) -> 0.10653284 | H41: =IFERROR(__xludf.DUMMYFUNCTION("FILTER(SemEval_2025_T2!$E$3:$E$132, REGEXMATCH(SemEval_2025_T2!$A$3:$A$132, ""(?i)"" & $H$21 &""_"" & $A41) )"),0.302676293297345) -> 0.30267629 | I41: =IFERROR(__xludf.DUMMYFUNCTION("FILTER(SemEval_2025_T2!$F$3:$F$132, REGEXMATCH(SemEval_2025_T2!$A$3:$A$132, ""(?i)"" & $H$21 &""_"" & $A41) )"),0.044550067970715) -> 0.044550068
A42: original_original | B42: =IFERROR(__xludf.DUMMYFUNCTION("FILTER(SemEval_2025_T2!$E$3:$E$132, REGEXMATCH(SemEval_2025_T2!$A$3:$A$132, ""(?i)"" & $B$21 &""_"" & $A42) )"),0.515748946083156) -> 0.51574895 | C42: =IFERROR(__xludf.DUMMYFUNCTION("FILTER(SemEval_2025_T2!$F$3:$F$132, REGEXMATCH(SemEval_2025_T2!$A$3:$A$132, ""(?i)"" & $B$21 &""_"" & $A42) )"),0.304809111760933) -> 0.30480911 | D42: =IFERROR(__xludf.DUMMYFUNCTION("FILTER(SemEval_2025_T2!$E$3:$E$132, REGEXMATCH(SemEval_2025_T2!$A$3:$A$132, ""(?i)"" & $D$21 &""_"" & $A42) )"),0.255187902448428) -> 0.2551879 | E42: =IFERROR(__xludf.DUMMYFUNCTION("FILTER(SemEval_2025_T2!$F$3:$F$132, REGEXMATCH(SemEval_2025_T2!$A$3:$A$132, ""(?i)"" & $D$21 &""_"" & $A42) )"),0.125488533980639) -> 0.12548853 | F42: =IFERROR(__xludf.DUMMYFUNCTION("FILTER(SemEval_2025_T2!$E$3:$E$132, REGEXMATCH(SemEval_2025_T2!$A$3:$A$132, ""(?i)"" & $F$21 &""_"" & $A42) )"),0.29827218687745) -> 0.29827219 | G42: =IFERROR(__xludf.DUMMYFUNCTION("FILTER(SemEval_2025_T2!$F$3:$F$132, REGEXMATCH(SemEval_2025_T2!$A$3:$A$132, ""(?i)"" & $F$21 &""_"" & $A42) )"),0.096927893451577) -> 0.096927893 | H42: =IFERROR(__xludf.DUMMYFUNCTION("FILTER(SemEval_2025_T2!$E$3:$E$132, REGEXMATCH(SemEval_2025_T2!$A$3:$A$132, ""(?i)"" & $H$21 &""_"" & $A42) )"),0.321656297795771) -> 0.3216563 | I42: =IFERROR(__xludf.DUMMYFUNCTION("FILTER(SemEval_2025_T2!$F$3:$F$132, REGEXMATCH(SemEval_2025_T2!$A$3:$A$132, ""(?i)"" & $H$21 &""_"" & $A42) )"),0.04430764314408) -> 0.044307643
...

Sheet RQ2
A1: RQ2 | B1: Is it better to use the original human defined descriptions of narratives or ask the models to rewrite / improve / extend them? | M1: ALL | P1: EN | Q1: HI | R1: PT | S1: BG | T1: RU | U1: Total
A2: dipro | B2: calme | D2: gemma | F2: exaone | H2: granite | L2: Number of models worst than original_original | O2: =COUNTIF(B5:I5,">0") + COUNTIF(B7:I7,">0") + COUNTIF(B9:I9,">0") + COUNTIF(B11:I11,">0") + COUNTIF(B13:I13,">0") + COUNTIF(B15:I15,">0") + COUNTIF(B24:I24,">0") + COUNTIF(B26:I26,">0") + COUNTIF(B28:I28,">0") + COUNTIF(B30:I30,">0") + COUNTIF(B32:I32,">0") + COUNTIF(B34:I34,">0") + COUNTIF(B41:I41,">0") + COUNTIF(B43:I43,">0") + COUNTIF(B45:I45,">0") + COUNTIF(B47:I47,">0") + COUNTIF(B49:I49,">0") + COUNTIF(B51:I51,">0") + COUNTIF(B58:I58,">0") + COUNTIF(B60:I60,">0") + COUNTIF(B62:I62,">0") + COUNTIF(B64:I64,">0") + COUNTIF(B66:I66,">0") + COUNTIF(B68:I68,">0") -> 143 | P2: 154 | Q2: 144 | R2: 160 | S2: 146 | T2: 143 | U2: =SUM(P2:T2) -> 747
A3: original_original | B3: =IFERROR(__xludf.DUMMYFUNCTION("FILTER(Dipromats!C$3:C$101, REGEXMATCH(Dipromats!$A$3:$A$101, ""(?i)"" & $A3) )"),0.638654812715595) -> 0.63865481 | C3: =IFERROR(__xludf.DUMMYFUNCTION("FILTER(Dipromats!D$3:D$101, REGEXMATCH(Dipromats!$A$3:$A$101, ""(?i)"" & $A3) )"),0.613462791622532) -> 0.61346279 | D3: =IFERROR(__xludf.DUMMYFUNCTION("FILTER(Dipromats!E$3:E$101, REGEXMATCH(Dipromats!$A$3:$A$101, ""(?i)"" & $A3) )"),0.624175131263906) -> 0.62417513 | E3: =IFERROR(__xludf.DUMMYFUNCTION("FILTER(Dipromats!F$3:F$101, REGEXMATCH(Dipromats!$A$3:$A$101, ""(?i)"" & $A3) )"),0.593223331315557) -> 0.59322333 | F3: =IFERROR(__xludf.DUMMYFUNCTION("FILTER(Dipromats!G$3:G$101, REGEXMATCH(Dipromats!$A$3:$A$101, ""(?i)"" & $A3) )"),0.572478446675392) -> 0.57247845 | G3: =IFERROR(__xludf.DUMMYFUNCTION("FILTER(Dipromats!H$3:H$101, REGEXMATCH(Dipromats!$A$3:$A$101, ""(?i)"" & $A3) )"),0.534765902917699) -> 0.5347659 | H3: =IFERROR(__xludf.DUMMYFUNCTION("FILTER(Dipromats!I$3:I$101, REGEXMATCH(Dipromats!$A$3:$A$101, ""(?i)"" & $A3) )"),0.335225441305954) -> 0.33522544 | I3: =IFERROR(__xludf.DUMMYFUNCTION("FILTER(Dipromats!J$3:J$101, REGEXMATCH(Dipromats!$A$3:$A$101, ""(?i)"" & $A3) )"),0.352567599779278) -> 0.3525676 | L3: Number of better than original_original | O3: =COUNTIF(B5:I5,"<0") + COUNTIF(B7:I7,"<0") + COUNTIF(B9:I9,"<0") + COUNTIF(B11:I11,"<0") + COUNTIF(B13:I13,"<0") + COUNTIF(B15:I15,"<0") + COUNTIF(B24:I24,"<0") + COUNTIF(B26:I26,"<0") + COUNTIF(B28:I28,"<0") + COUNTIF(B30:I30,"<0") + COUNTIF(B32:I32,"<0") + COUNTIF(B34:I34,"<0") + COUNTIF(B41:I41,"<0") + COUNTIF(B43:I43,"<0") + COUNTIF(B45:I45,"<0") + COUNTIF(B47:I47,"<0") + COUNTIF(B49:I49,"<0") + COUNTIF(B51:I51,"<0") + COUNTIF(B58:I58,"<0") + COUNTIF(B60:I60,"<0") + COUNTIF(B62:I62,"<0") + COUNTIF(B64:I64,"<0") + COUNTIF(B66:I66,"<0") + COUNTIF(B68:I68,"<0") -> 29 | P3: 20 | Q3: 28 | R3: 12 | S3: 26 | T3: 29 | U3: =SUM(P3:T3) -> 115
A4: own_title | B4: =IFERROR(__xludf.DUMMYFUNCTION("FILTER(Dipromats!C$3:C$101, REGEXMATCH(Dipromats!$A$3:$A$101, ""(?i)"" & $A4) )"),0.621040280030557) -> 0.62104028 | C4: =IFERROR(__xludf.DUMMYFUNCTION("FILTER(Dipromats!D$3:D$101, REGEXMATCH(Dipromats!$A$3:$A$101, ""(?i)"" & $A4) )"),0.571358654012934) -> 0.57135865 | D4: =IFERROR(__xludf.DUMMYFUNCTION("FILTER(Dipromats!E$3:E$101, REGEXMATCH(Dipromats!$A$3:$A$101, ""(?i)"" & $A4) )"),0.57620875615112) -> 0.57620876 | E4: =IFERROR(__xludf.DUMMYFUNCTION("FILTER(Dipromats!F$3:F$101, REGEXMATCH(Dipromats!$A$3:$A$101, ""(?i)"" & $A4) )"),0.531274741257453) -> 0.53127474 | F4: =IFERROR(__xludf.DUMMYFUNCTION("FILTER(Dipromats!G$3:G$101, REGEXMATCH(Dipromats!$A$3:$A$101, ""(?i)"" & $A4) )"),0.506150051999198) -> 0.50615005 | G4: =IFERROR(__xludf.DUMMYFUNCTION("FILTER(Dipromats!H$3:H$101, REGEXMATCH(Dipromats!$A$3:$A$101, ""(?i)"" & $A4) )"),0.483697863941618) -> 0.48369786 | H4: =IFERROR(__xludf.DUMMYFUNCTION("FILTER(Dipromats!I$3:I$101, REGEXMATCH(Dipromats!$A$3:$A$101, ""(?i)"" & $A4) )"),0.286129356930116) -> 0.28612936 | I4: =IFERROR(__xludf.DUMMYFUNCTION("FILTER(Dipromats!J$3:J$101, REGEXMATCH(Dipromats!$A$3:$A$101, ""(?i)"" & $A4) )"),0.29837198245895) -> 0.29837198 | L4: Percentage of worst models | O4: =100*O2/(O3+O2) -> 83.139535 | P4: 88.505747 | Q4: 83.72093 | R4: 93.023256 | S4: 84.883721 | T4: 83.139535 | U4: =(U2*100)/(U2+U3) -> 86.658933
A5: delta_own_title | B5: =B3-B4 -> 0.017614533 | C5: =C3-C4 -> 0.042104138 | D5: =D3-D4 -> 0.047966375 | E5: =E3-E4 -> 0.06194859 | F5: =F3-F4 -> 0.066328395 | G5: =G3-G4 -> 0.051068039 | H5: =H3-H4 -> 0.049096084 | I5: =I3-I4 -> 0.054195617 | J5: =AVERAGE(B5:I5) -> 0.048790221 | L5: Percentage of better models | O5: =100*O3/(O2+O3) -> 16.860465 | P5: 11.494253 | Q5: 16.27907 | R5: 6.9767442 | S5: 15.116279 | T5: 16.860465 | U5: =100-U4 -> 13.341067
A6: gpt_title | B6: =IFERROR(__xludf.DUMMYFUNCTION("FILTER(Dipromats!C$3:C$101, REGEXMATCH(Dipromats!$A$3:$A$101, ""(?i)"" & $A6) )"),0.608500522443986) -> 0.60850052 | C6: =IFERROR(__xludf.DUMMYFUNCTION("FILTER(Dipromats!D$3:D$101, REGEXMATCH(Dipromats!$A$3:$A$101, ""(?i)"" & $A6) )"),0.565727300132339) -> 0.5657273 | D6: =IFERROR(__xludf.DUMMYFUNCTION("FILTER(Dipromats!E$3:E$101, REGEXMATCH(Dipromats!$A$3:$A$101, ""(?i)"" & $A6) )"),0.583927636565709) -> 0.58392764 | E6: =IFERROR(__xludf.DUMMYFUNCTION("FILTER(Dipromats!F$3:F$101, REGEXMATCH(Dipromats!$A$3:$A$101, ""(?i)"" & $A6) )"),0.523712547832867) -> 0.52371255 | F6: =IFERROR(__xludf.DUMMYFUNCTION("FILTER(Dipromats!G$3:G$101, REGEXMATCH(Dipromats!$A$3:$A$101, ""(?i)"" & $A6) )"),0.524902705155418) -> 0.52490271 | G6: =IFERROR(__xludf.DUMMYFUNCTION("FILTER(Dipromats!H$3:H$101, REGEXMATCH(Dipromats!$A$3:$A$101, ""(?i)"" & $A6) )"),0.490732657736496) -> 0.49073266 | H6: =IFERROR(__xludf.DUMMYFUNCTION("FILTER(Dipromats!I$3:I$101, REGEXMATCH(Dipromats!$A$3:$A$101, ""(?i)"" & $A6) )"),0.267289569310955) -> 0.26728957 | I6: =IFERROR(__xludf.DUMMYFUNCTION("FILTER(Dipromats!J$3:J$101, REGEXMATCH(Dipromats!$A$3:$A$101, ""(?i)"" & $A6) )"),0.297865824391553) -> 0.29786582
A7: delta_gpt_title | B7: =B3-B6 -> 0.03015429 | C7: =C3-C6 -> 0.047735491 | D7: =D3-D6 -> 0.040247495 | E7: =E3-E6 -> 0.069510783 | F7: =F3-F6 -> 0.047575742 | G7: =G3-G6 -> 0.044033245 | H7: =H3-H6 -> 0.067935872 | I7: =I3-I6 -> 0.054701775 | J7: =AVERAGE(B7:I7) -> 0.050236837
A8: own_description | B8: =IFERROR(__xludf.DUMMYFUNCTION("FILTER(Dipromats!C$3:C$101, REGEXMATCH(Dipromats!$A$3:$A$101, ""(?i)"" & $A8), NOT(REGEXMATCH(Dipromats!$A$3:$A$101, ""(?i)complete"")) )"),0.631787462260468) -> 0.63178746 | C8: =IFERROR(__xludf.DUMMYFUNCTION("FILTER(Dipromats!D$3:D$101, REGEXMATCH(Dipromats!$A$3:$A$101, ""(?i)"" & $A8), NOT(REGEXMATCH(Dipromats!$A$3:$A$101, ""(?i)complete"")) )"),0.618216042484733) -> 0.61821604 | D8: =IFERROR(__xludf.DUMMYFUNCTION("FILTER(Dipromats!E$3:E$101, REGEXMATCH(Dipromats!$A$3:$A$101, ""(?i)"" & $A8), NOT(REGEXMATCH(Dipromats!$A$3:$A$101, ""(?i)complete"")) )"),0.586439666342686) -> 0.58643967 | E8: =IFERROR(__xludf.DUMMYFUNCTION("FILTER(Dipromats!F$3:F$101, REGEXMATCH(Dipromats!$A$3:$A$101, ""(?i)"" & $A8), NOT(REGEXMATCH(Dipromats!$A$3:$A$101, ""(?i)complete"")) )"),0.569895182181278) -> 0.56989518 | F8: =IFERROR(__xludf.DUMMYFUNCTION("FILTER(Dipromats!G$3:G$101, REGEXMATCH(Dipromats!$A$3:$A$101, ""(?i)"" & $A8), NOT(REGEXMATCH(Dipromats!$A$3:$A$101, ""(?i)complete"")) )"),0.546258468663482) -> 0.54625847 | G8: =IFERROR(__xludf.DUMMYFUNCTION("FILTER(Dipromats!H$3:H$101, REGEXMATCH(Dipromats!$A$3:$A$101, ""(?i)"" & $A8), NOT(REGEXMATCH(Dipromats!$A$3:$A$101, ""(?i)complete"")) )"),0.512012998082786) -> 0.512013 | H8: =IFERROR(__xludf.DUMMYFUNCTION("FILTER(Dipromats!I$3:I$101, REGEXMATCH(Dipromats!$A$3:$A$101, ""(?i)"" & $A8), NOT(REGEXMATCH(Dipromats!$A$3:$A$101, ""(?i)complete"")) )"),0.288938661231155) -> 0.28893866 | I8: =IFERROR(__xludf.DUMMYFUNCTION("FILTER(Dipromats!J$3:J$101, REGEXMATCH(Dipromats!$A$3:$A$101, ""(?i)"" & $A8), NOT(REGEXMATCH(Dipromats!$A$3:$A$101, ""(?i)complete"")) )"),0.329512617172151) -> 0.32951262
A9: delta_own_description | B9: =B3-B8 -> 0.0068673505 | C9: =C3-C8 -> -0.0047532509 | D9: =D3-D8 -> 0.037735465 | E9: =E3-E8 -> 0.023328149 | F9: =F3-F8 -> 0.026219978 | G9: =G3-G8 -> 0.022752905 | H9: =H3-H8 -> 0.04628678 | I9: =I3-I8 -> 0.023054983 | J9: =AVERAGE(B9:I9) -> 0.022686545
A10: gpt_description | B10: =IFERROR(__xludf.DUMMYFUNCTION("FILTER(Dipromats!C$3:C$101, REGEXMATCH(Dipromats!$A$3:$A$101, ""(?i)"" & $A10), NOT(REGEXMATCH(Dipromats!$A$3:$A$101, ""(?i)complete"")) )"),0.640317661477475) -> 0.64031766 | C10: =IFERROR(__xludf.DUMMYFUNCTION("FILTER(Dipromats!D$3:D$101, REGEXMATCH(Dipromats!$A$3:$A$101, ""(?i)"" & $A10), NOT(REGEXMATCH(Dipromats!$A$3:$A$101, ""(?i)complete"")) )"),0.61354665612827) -> 0.61354666 | D10: =IFERROR(__xludf.DUMMYFUNCTION("FILTER(Dipromats!E$3:E$101, REGEXMATCH(Dipromats!$A$3:$A$101, ""(?i)"" & $A10), NOT(REGEXMATCH(Dipromats!$A$3:$A$101, ""(?i)complete"")) )"),0.613750839783722) -> 0.61375084 | E10: =IFERROR(__xludf.DUMMYFUNCTION("FILTER(Dipromats!F$3:F$101, REGEXMATCH(Dipromats!$A$3:$A$101, ""(?i)"" & $A10), NOT(REGEXMATCH(Dipromats!$A$3:$A$101, ""(?i)complete"")) )"),0.578681917130575) -> 0.57868192 | F10: =IFERROR(__xludf.DUMMYFUNCTION("FILTER(Dipromats!G$3:G$101, REGEXMATCH(Dipromats!$A$3:$A$101, ""(?i)"" & $A10), NOT(REGEXMATCH(Dipromats!$A$3:$A$101, ""(?i)complete"")) )"),0.545763744390765) -> 0.54576374 | G10: =IFERROR(__xludf.DUMMYFUNCTION("FILTER(Dipromats!H$3:H$101, REGEXMATCH(Dipromats!$A$3:$A$101, ""(?i)"" & $A10), NOT(REGEXMATCH(Dipromats!$A$3:$A$101, ""(?i)complete"")) )"),0.524262991587101) -> 0.52426299 | H10: =IFERROR(__xludf.DUMMYFUNCTION("FILTER(Dipromats!I$3:I$101, REGEXMATCH(Dipromats!$A$3:$A$101, ""(?i)"" & $A10), NOT(REGEXMATCH(Dipromats!$A$3:$A$101, ""(?i)complete"")) )"),0.284838731621514) -> 0.28483873 | I10: =IFERROR(__xludf.DUMMYFUNCTION("FILTER(Dipromats!J$3:J$101, REGEXMATCH(Dipromats!$A$3:$A$101, ""(?i)"" & $A10), NOT(REGEXMATCH(Dipromats!$A$3:$A$101, ""(?i)complete"")) )"),0.300772443809359) -> 0.30077244
A11: delta_gpt_description | B11: =B3-B10 -> -0.0016628488 | C11: =C3-C10 -> -8.3864506e-05 | D11: =D3-D10 -> 0.010424291 | E11: =E3-E10 -> 0.014541414 | F11: =F3-F10 -> 0.026714702 | G11: =G3-G10 -> 0.010502911 | H11: =H3-H10 -> 0.05038671 | I11: =I3-I10 -> 0.051795156 | J11: =AVERAGE(B11:I11) -> 0.020327309
A12: own_description_complete | B12: =IFERROR(__xludf.DUMMYFUNCTION("FILTER(Dipromats!C$3:C$101, REGEXMATCH(Dipromats!$A$3:$A$101, ""(?i)"" & $A12) )"),0.632355163340107) -> 0.63235516 | C12: =IFERROR(__xludf.DUMMYFUNCTION("FILTER(Dipromats!D$3:D$101, REGEXMATCH(Dipromats!$A$3:$A$101, ""(?i)"" & $A12) )"),0.606225827187698) -> 0.60622583 | D12: =IFERROR(__xludf.DUMMYFUNCTION("FILTER(Dipromats!E$3:E$101, REGEXMATCH(Dipromats!$A$3:$A$101, ""(?i)"" & $A12) )"),0.535090217689681) -> 0.53509022 | E12: =IFERROR(__xludf.DUMMYFUNCTION("FILTER(Dipromats!F$3:F$101, REGEXMATCH(Dipromats!$A$3:$A$101, ""(?i)"" & $A12) )"),0.477750371254548) -> 0.47775037 | F12: =IFERROR(__xludf.DUMMYFUNCTION("FILTER(Dipromats!G$3:G$101, REGEXMATCH(Dipromats!$A$3:$A$101, ""(?i)"" & $A12) )"),0.457442229094388) -> 0.45744223 | G12: =IFERROR(__xludf.DUMMYFUNCTION("FILTER(Dipromats!H$3:H$101, REGEXMATCH(Dipromats!$A$3:$A$101, ""(?i)"" & $A12) )"),0.427462251024684) -> 0.42746225 | H12: =IFERROR(__xludf.DUMMYFUNCTION("FILTER(Dipromats!I$3:I$101, REGEXMATCH(Dipromats!$A$3:$A$101, ""(?i)"" & $A12) )"),0.245367655632764) -> 0.24536766 | I12: =IFERROR(__xludf.DUMMYFUNCTION("FILTER(Dipromats!J$3:J$101, REGEXMATCH(Dipromats!$A$3:$A$101, ""(?i)"" & $A12) )"),0.282654794342775) -> 0.28265479
A13: delta_own_description_comp | B13: =B3-B12 -> 0.0062996494 | C13: =C3-C12 -> 0.0072369644 | D13: =D3-D12 -> 0.089084914 | E13: =E3-E12 -> 0.11547296 | F13: =F3-F12 -> 0.11503622 | G13: =G3-G12 -> 0.10730365 | H13: =H3-H12 -> 0.089857786 | I13: =I3-I12 -> 0.069912805 | J13: =AVERAGE(B13:I13) -> 0.075025619
A14: gpt_description_complete | B14: =IFERROR(__xludf.DUMMYFUNCTION("FILTER(Dipromats!C$3:C$101, REGEXMATCH(Dipromats!$A$3:$A$101, ""(?i)"" & $A14) )"),0.626620634285161) -> 0.62662063 | C14: =IFERROR(__xludf.DUMMYFUNCTION("FILTER(Dipromats!D$3:D$101, REGEXMATCH(Dipromats!$A$3:$A$101, ""(?i)"" & $A14) )"),0.604801060798369) -> 0.60480106 | D14: =IFERROR(__xludf.DUMMYFUNCTION("FILTER(Dipromats!E$3:E$101, REGEXMATCH(Dipromats!$A$3:$A$101, ""(?i)"" & $A14) )"),0.274748595417237) -> 0.2747486 | E14: =IFERROR(__xludf.DUMMYFUNCTION("FILTER(Dipromats!F$3:F$101, REGEXMATCH(Dipromats!$A$3:$A$101, ""(?i)"" & $A14) )"),0.380177808740426) -> 0.38017781 | F14: =IFERROR(__xludf.DUMMYFUNCTION("FILTER(Dipromats!G$3:G$101, REGEXMATCH(Dipromats!$A$3:$A$101, ""(?i)"" & $A14) )"),0.484593915089339) -> 0.48459392 | G14: =IFERROR(__xludf.DUMMYFUNCTION("FILTER(Dipromats!H$3:H$101, REGEXMATCH(Dipromats!$A$3:$A$101, ""(?i)"" & $A14) )"),0.437797137788191) -> 0.43779714 | H14: =IFERROR(__xludf.DUMMYFUNCTION("FILTER(Dipromats!I$3:I$101, REGEXMATCH(Dipromats!$A$3:$A$101, ""(?i)"" & $A14) )"),0.220620940157727) -> 0.22062094 | I14: =IFERROR(__xludf.DUMMYFUNCTION("FILTER(Dipromats!J$3:J$101, REGEXMATCH(Dipromats!$A$3:$A$101, ""(?i)"" & $A14) )"),0.271705614091627) -> 0.27170561
A15: delta_gpt_description_comp | B15: =B3-B14 -> 0.012034178 | C15: =C3-C14 -> 0.0086617308 | D15: =D3-D14 -> 0.34942654 | E15: =E3-E14 -> 0.21304552 | F15: =F3-F14 -> 0.087884532 | G15: =G3-G14 -> 0.096968765 | H15: =H3-H14 -> 0.1146045 | I15: =I3-I14 -> 0.080861986 | J15: =AVERAGE(B15:I15) -> 0.12043597
B16: =AVERAGE(B5,B7,B9,B11,B13,B15) -> 0.011884525 | C16: =AVERAGE(C5,C7,C9,C11,C13,C15) -> 0.016816868 | D16: =AVERAGE(D5,D7,D9,D11,D13,D15) -> 0.095814179 | E16: =AVERAGE(E5,E7,E9,E11,E13,E15) -> 0.08297457 | F16: =AVERAGE(F5,F7,F9,F11,F13,F15) -> 0.061626594 | G16: =AVERAGE(G5,G7,G9,G11,G13,G15) -> 0.055438253 | H16: =AVERAGE(H5,H7,H9,H11,H13,H15) -> 0.069694622 | I16: =AVERAGE(I5,I7,I9,I11,I13,I15) -> 0.05575372
B17: =AVERAGE(B16:C16) -> 0.014350697 | D17: =AVERAGE(D16:E16) -> 0.089394375 | F17: =AVERAGE(F16:G16) -> 0.058532424 | H17: =AVERAGE(H16:I16) -> 0.062724171
A21: 3_steps | B21: calme | D21: gemma | F21: exaone | H21: granite
A22: original_original | B22: =IFERROR(__xludf.DUMMYFUNCTION("FILTER(SemEval_2025_T2!$G$3:$G$132, REGEXMATCH(SemEval_2025_T2!$A$3:$A$132, ""(?i)"" & $B$21 &""_"" & $A22) )"),0.514035206022048) -> 0.51403521 | C22: =IFERROR(__xludf.DUMMYFUNCTION("FILTER(SemEval_2025_T2!$H$3:$H$132, REGEXMATCH(SemEval_2025_T2!$A$3:$A$132, ""(?i)"" & $B$21 &""_"" & $A22) )"),0.307645133386631) -> 0.30764513 | D22: =IFERROR(__xludf.DUMMYFUNCTION("FILTER(SemEval_2025_T2!$G$3:$G$132, REGEXMATCH(SemEval_2025_T2!$A$3:$A$132, ""(?i)"" & $D$21 &""_"" & $A22) )"),0.381269392078906) -> 0.38126939 | E22: =IFERROR(__xludf.DUMMYFUNCTION("FILTER(SemEval_2025_T2!$H$3:$H$132, REGEXMATCH(SemEval_2025_T2!$A$3:$A$132, ""(?i)"" & $D$21 &""_"" & $A22) )"),0.213641884382488) -> 0.21364188 | F22: =IFERROR(__xludf.DUMMYFUNCTION("FILTER(SemEval_2025_T2!$G$3:$G$132, REGEXMATCH(SemEval_2025_T2!$A$3:$A$132, ""(?i)"" & $F$21 &""_"" & $A22) )"),0.297130229419703) -> 0.29713023 | G22: =IFERROR(__xludf.DUMMYFUNCTION("FILTER(SemEval_2025_T2!$H$3:$H$132, REGEXMATCH(SemEval_2025_T2!$A$3:$A$132, ""(?i)"" & $F$21 &""_"" & $A22) )"),0.118694163326551) -> 0.11869416 | H22: =IFERROR(__xludf.DUMMYFUNCTION("FILTER(SemEval_2025_T2!$G$3:$G$132, REGEXMATCH(SemEval_2025_T2!$A$3:$A$132, ""(?i)"" & $H$21 &""_"" & $A22) )"),0.238378224888286) -> 0.23837822 | I22: =IFERROR(__xludf.DUMMYFUNCTION("FILTER(SemEval_2025_T2!$H$3:$H$132, REGEXMATCH(SemEval_2025_T2!$A$3:$A$132, ""(?i)"" & $H$21 &""_"" & $A22) )"),0.083454375288068) -> 0.083454375
A23: only_title | B23: =IFERROR(__xludf.DUMMYFUNCTION("FILTER(SemEval_2025_T2!$G$3:$G$132, REGEXMATCH(SemEval_2025_T2!$A$3:$A$132, ""(?i)"" & $B$21 &""_"" & $A23) )"),0.443146947744113) -> 0.44314695 | C23: =IFERROR(__xludf.DUMMYFUNCTION("FILTER(SemEval_2025_T2!$H$3:$H$132, REGEXMATCH(SemEval_2025_T2!$A$3:$A$132, ""(?i)"" & $B$21 &""_"" & $A23) )"),0.278619253553464) -> 0.27861925 | D23: =IFERROR(__xludf.DUMMYFUNCTION("FILTER(SemEval_2025_T2!$G$3:$G$132, REGEXMATCH(SemEval_2025_T2!$A$3:$A$132, ""(?i)"" & $D$21 &""_"" & $A23) )"),0.183951176893282) -> 0.18395118 | E23: =IFERROR(__xludf.DUMMYFUNCTION("FILTER(SemEval_2025_T2!$H$3:$H$132, REGEXMATCH(SemEval_2025_T2!$A$3:$A$132, ""(?i)"" & $D$21 &""_"" & $A23) )"),0.076478375942546) -> 0.076478376 | F23: =IFERROR(__xludf.DUMMYFUNCTION("FILTER(SemEval_2025_T2!$G$3:$G$132, REGEXMATCH(SemEval_2025_T2!$A$3:$A$132, ""(?i)"" & $F$21 &""_"" & $A23) )"),0.322483844225949) -> 0.32248384 | G23: =IFERROR(__xludf.DUMMYFUNCTION("FILTER(SemEval_2025_T2!$H$3:$H$132, REGEXMATCH(SemEval_2025_T2!$A$3:$A$132, ""(?i)"" & $F$21 &""_"" & $A23) )"),0.137031714619164) -> 0.13703171 | H23: =IFERROR(__xludf.DUMMYFUNCTION("FILTER(SemEval_2025_T2!$G$3:$G$132, REGEXMATCH(SemEval_2025_T2!$A$3:$A$132, ""(?i)"" & $H$21 &""_"" & $A23) )"),0.159618888713625) -> 0.15961889 | I23: =IFERROR(__xludf.DUMMYFUNCTION("FILTER(SemEval_2025_T2!$H$3:$H$132, REGEXMATCH(SemEval_2025_T2!$A$3:$A$132, ""(?i)"" & $H$21 &""_"" & $A23) )"),0.051741760021139) -> 0.05174176 | P23: EN | Q23: HI | R23: PT | S23: BG | T23: RU | U23: Total
A24: delta_own_title | B24: =B$22-B23 -> 0.070888258 | C24: =C$22-C23 -> 0.02902588 | D24: =D$22-D23 -> 0.19731822 | E24: =E$22-E23 -> 0.13716351 | F24: =F$22-F23 -> -0.025353615 | G24: =G$22-G23 -> -0.018337551 | H24: =H$22-H23 -> 0.078759336 | I24: =I$22-I23 -> 0.031712615 | J24: =AVERAGE(B24,D24,F24,H24) -> 0.080403049 | K24: =AVERAGE(C24,E24,G24,I24) -> 0.044891113 | L24: =AVERAGE(J24,K24) -> 0.062647081 | N24: delta_own_title | O24: =AVERAGE(L24,L41,L58) -> 0.023132636 | P24: 0.03900494 | Q24: 0.020250821 | R24: 0.045974636 | S24: 0.034394169 | T24: 0.023132636 | U24: =AVERAGE(P24:T24) -> 0.03255144
A25: zero_shot_gpt_only_title | B25: =IFERROR(__xludf.DUMMYFUNCTION("FILTER(SemEval_2025_T2!$G$3:$G$132, REGEXMATCH(SemEval_2025_T2!$A$3:$A$132, ""(?i)"" & $B$21 &""_"" & $A25) )"),0.413172598162071) -> 0.4131726 | C25: =IFERROR(__xludf.DUMMYFUNCTION("FILTER(SemEval_2025_T2!$H$3:$H$132, REGEXMATCH(SemEval_2025_T2!$A$3:$A$132, ""(?i)"" & $B$21 &""_"" & $A25) )"),0.238469869626549) -> 0.23846987 | D25: =IFERROR(__xludf.DUMMYFUNCTION("FILTER(SemEval_2025_T2!$G$3:$G$132, REGEXMATCH(SemEval_2025_T2!$A$3:$A$132, ""(?i)"" & $D$21 &""_"" & $A25) )"),0.201656347341367) -> 0.20165635 | E25: =IFERROR(__xludf.DUMMYFUNCTION("FILTER(SemEval_2025_T2!$H$3:$H$132, REGEXMATCH(SemEval_2025_T2!$A$3:$A$132, ""(?i)"" & $D$21 &""_"" & $A25) )"),0.098389118476481) -> 0.098389118 | F25: =IFERROR(__xludf.DUMMYFUNCTION("FILTER(SemEval_2025_T2!$G$3:$G$132, REGEXMATCH(SemEval_2025_T2!$A$3:$A$132, ""(?i)"" & $F$21 &""_"" & $A25) )"),0.266104055009318) -> 0.26610406 | G25: =IFERROR(__xludf.DUMMYFUNCTION("FILTER(SemEval_2025_T2!$H$3:$H$132, REGEXMATCH(SemEval_2025_T2!$A$3:$A$132, ""(?i)"" & $F$21 &""_"" & $A25) )"),0.099810456390213) -> 0.099810456 | H25: =IFERROR(__xludf.DUMMYFUNCTION("FILTER(SemEval_2025_T2!$G$3:$G$132, REGEXMATCH(SemEval_2025_T2!$A$3:$A$132, ""(?i)"" & $H$21 &""_"" & $A25) )"),0.246870696554907) -> 0.2468707 | I25: =IFERROR(__xludf.DUMMYFUNCTION("FILTER(SemEval_2025_T2!$H$3:$H$132, REGEXMATCH(SemEval_2025_T2!$A$3:$A$132, ""(?i)"" & $H$21 &""_"" & $A25) )"),0.059954252922066) -> 0.059954253 | N25: delta_gpt_title | O25: =AVERAGE(L26,L43,L60) -> 0.024582464 | P25: 0.03837001 | Q25: 0.02057498 | R25: 0.05159966 | S25: 0.035957518 | T25: 0.024582464 | U25: =AVERAGE(P25:T25) -> 0.034216926
A26: delta_gpt_title | B26: =B$22-B25 -> 0.10086261 | C26: =C$22-C25 -> 0.069175264 | D26: =D$22-D25 -> 0.17961304 | E26: =E$22-E25 -> 0.11525277 | F26: =F$22-F25 -> 0.031026174 | G26: =G$22-G25 -> 0.018883707 | H26: =H$22-H25 -> -0.0084924717 | I26: =I$22-I25 -> 0.023500122 | J26: =AVERAGE(B26,D26,F26,H26) -> 0.075752339 | K26: =AVERAGE(C26,E26,G26,I26) -> 0.056702965 | L26: =AVERAGE(J26,K26) -> 0.066227652 | N26: delta_own_description | O26: =AVERAGE(L28,L45,L62) -> 0.015253893 | P26: 0.022904303 | Q26: 0.0177053 | R26: 0.046244694 | S26: 0.028120029 | T26: 0.015253893 | U26: =AVERAGE(P26:T26) -> 0.026045644
