Workbook

Sheet RQ1
A1: RQ1 | B1: Are narrative titles enough or models benefit from an extended narrative description? | M1: ALL
A2: dipro | B2: calme | D2: gemma | F2: exaone | H2: granite | L2: Number of models better than no_no | O2: =COUNTIF(B5:I5,"<0") + COUNTIF(B7:I7,"<0") + COUNTIF(B9:I9,"<0") + COUNTIF(B11:I11,"<0") + COUNTIF(B13:I13,"<0") + COUNTIF(B15:I15,"<0") + COUNTIF(B17:I17,"<0") + COUNTIF(B24:I24,"<0") + COUNTIF(B26:I26,"<0") + COUNTIF(B28:I28,"<0") + COUNTIF(B30:I30,"<0") + COUNTIF(B32:I32,"<0") + COUNTIF(B34:I34,"<0") + COUNTIF(B36:I36,"<0") + COUNTIF(B43:I43,"<0") + COUNTIF(B45:I45,"<0") + COUNTIF(B47:I47,"<0") + COUNTIF(B49:I49,"<0") + COUNTIF(B51:I51,"<0") + COUNTIF(B53:I53,"<0") + COUNTIF(B55:I55,"<0") + COUNTIF(B62:I62,"<0") + COUNTIF(B64:I64,"<0") + COUNTIF(B66:I66,"<0") + COUNTIF(B68:I68,"<0") + COUNTIF(B69:I69,"<0") + COUNTIF(B70:I70,"<0") + COUNTIF(B72:I72,"<0") + COUNTIF(B74:I74,"<0") -> 62
A3: no_no | B3: =IFERROR(__xludf.DUMMYFUNCTION("FILTER(Dipromats!C$3:C$101, REGEXMATCH(Dipromats!$A$3:$A$101, ""(?i)"" & $A3) )"),0.634504615288617) -> 0.63450462 | C3: =IFERROR(__xludf.DUMMYFUNCTION("FILTER(Dipromats!D$3:D$101, REGEXMATCH(Dipromats!$A$3:$A$101, ""(?i)"" & $A3) )"),0.583394320061881) -> 0.58339432 | D3: =IFERROR(__xludf.DUMMYFUNCTION("FILTER(Dipromats!E$3:E$101, REGEXMATCH(Dipromats!$A$3:$A$101, ""(?i)"" & $A3) )"),0.612546907727468) -> 0.61254691 | E3: =IFERROR(__xludf.DUMMYFUNCTION("FILTER(Dipromats!F$3:F$101, REGEXMATCH(Dipromats!$A$3:$A$101, ""(?i)"" & $A3) )"),0.564694414756619) -> 0.56469441 | F3: =IFERROR(__xludf.DUMMYFUNCTION("FILTER(Dipromats!G$3:G$101, REGEXMATCH(Dipromats!$A$3:$A$101, ""(?i)"" & $A3) )"),0.551936514723647) -> 0.55193651 | G3: =IFERROR(__xludf.DUMMYFUNCTION("FILTER(Dipromats!H$3:H$101, REGEXMATCH(Dipromats!$A$3:$A$101, ""(?i)"" & $A3) )"),0.498994997427713) -> 0.498995 | H3: =IFERROR(__xludf.DUMMYFUNCTION("FILTER(Dipromats!I$3:I$101, REGEXMATCH(Dipromats!$A$3:$A$101, ""(?i)"" & $A3) )"),0.333605146281453) -> 0.33360515 | I3: =IFERROR(__xludf.DUMMYFUNCTION("FILTER(Dipromats!J$3:J$101, REGEXMATCH(Dipromats!$A$3:$A$101, ""(?i)"" & $A3) )"),0.367508834746624) -> 0.36750883 | L3: Number of models worse than no_no | O3: =COUNTIF(B5:I5,">0") + COUNTIF(B7:I7,">0") + COUNTIF(B9:I9,">0") + COUNTIF(B11:I11,">0") + COUNTIF(B13:I13,">0") + COUNTIF(B15:I15,">0") + COUNTIF(B17:I17,">0") + COUNTIF(B24:I24,">0") + COUNTIF(B26:I26,">0") + COUNTIF(B28:I28,">0") + COUNTIF(B30:I30,">0") + COUNTIF(B32:I32,">0") + COUNTIF(B34:I34,">0") + COUNTIF(B36:I36,">0") + COUNTIF(B43:I43,">0") + COUNTIF(B45:I45,">0") + COUNTIF(B47:I47,">0") + COUNTIF(B49:I49,">0") + COUNTIF(B51:I51,">0") + COUNTIF(B53:I53,">0") + COUNTIF(B55:I55,">0") + COUNTIF(B62:I62,">0") + COUNTIF(B64:I64,">0") + COUNTIF(B66:I66,">0") + COUNTIF(B68:I68,">0") + COUNTIF(B69:I69,">0") + COUNTIF(B70:I70,">0") + COUNTIF(B72:I72,">0") + COUNTIF(B74:I74,">0") -> 156
A4: original_original | B4: =IFERROR(__xludf.DUMMYFUNCTION("FILTER(Dipromats!C$3:C$101, REGEXMATCH(Dipromats!$A$3:$A$101, ""(?i)"" & $A4) )"),0.638654812715595) -> 0.63865481 | C4: =IFERROR(__xludf.DUMMYFUNCTION("FILTER(Dipromats!D$3:D$101, REGEXMATCH(Dipromats!$A$3:$A$101, ""(?i)"" & $A4) )"),0.613462791622532) -> 0.61346279 | D4: =IFERROR(__xludf.DUMMYFUNCTION("FILTER(Dipromats!E$3:E$101, REGEXMATCH(Dipromats!$A$3:$A$101, ""(?i)"" & $A4) )"),0.624175131263906) -> 0.62417513 | E4: =IFERROR(__xludf.DUMMYFUNCTION("FILTER(Dipromats!F$3:F$101, REGEXMATCH(Dipromats!$A$3:$A$101, ""(?i)"" & $A4) )"),0.593223331315557) -> 0.59322333 | F4: =IFERROR(__xludf.DUMMYFUNCTION("FILTER(Dipromats!G$3:G$101, REGEXMATCH(Dipromats!$A$3:$A$101, ""(?i)"" & $A4) )"),0.572478446675392) -> 0.57247845 | G4: =IFERROR(__xludf.DUMMYFUNCTION("FILTER(Dipromats!H$3:H$101, REGEXMATCH(Dipromats!$A$3:$A$101, ""(?i)"" & $A4) )"),0.534765902917699) -> 0.5347659 | H4: =IFERROR(__xludf.DUMMYFUNCTION("FILTER(Dipromats!I$3:I$101, REGEXMATCH(Dipromats!$A$3:$A$101, ""(?i)"" & $A4) )"),0.335225441305954) -> 0.33522544 | I4: =IFERROR(__xludf.DUMMYFUNCTION("FILTER(Dipromats!J$3:J$101, REGEXMATCH(Dipromats!$A$3:$A$101, ""(?i)"" & $A4) )"),0.352567599779278) -> 0.3525676 | L4: Percentage of better models | O4: =100*O2/(O3+O2) -> 28.440367
A5: delta_original | B5: =B3-B4 -> -0.0041501974 | C5: =C3-C4 -> -0.030068472 | D5: =D3-D4 -> -0.011628224 | E5: =E3-E4 -> -0.028528917 | F5: =F3-F4 -> -0.020541932 | G5: =G3-G4 -> -0.035770905 | H5: =H3-H4 -> -0.001620295 | I5: =I3-I4 -> 0.014941235 | J5: =AVERAGE(B5:I5) -> -0.014670963 | L5: Percentage of worst models | O5: =100*O3/(O2+O3) -> 71.559633
A6: own_title | B6: =IFERROR(__xludf.DUMMYFUNCTION("FILTER(Dipromats!C$3:C$101, REGEXMATCH(Dipromats!$A$3:$A$101, ""(?i)"" & $A6) )"),0.621040280030557) -> 0.62104028 | C6: =IFERROR(__xludf.DUMMYFUNCTION("FILTER(Dipromats!D$3:D$101, REGEXMATCH(Dipromats!$A$3:$A$101, ""(?i)"" & $A6) )"),0.571358654012934) -> 0.57135865 | D6: =IFERROR(__xludf.DUMMYFUNCTION("FILTER(Dipromats!E$3:E$101, REGEXMATCH(Dipromats!$A$3:$A$101, ""(?i)"" & $A6) )"),0.57620875615112) -> 0.57620876 | E6: =IFERROR(__xludf.DUMMYFUNCTION("FILTER(Dipromats!F$3:F$101, REGEXMATCH(Dipromats!$A$3:$A$101, ""(?i)"" & $A6) )"),0.531274741257453) -> 0.53127474 | F6: =IFERROR(__xludf.DUMMYFUNCTION("FILTER(Dipromats!G$3:G$101, REGEXMATCH(Dipromats!$A$3:$A$101, ""(?i)"" & $A6) )"),0.506150051999198) -> 0.50615005 | G6: =IFERROR(__xludf.DUMMYFUNCTION("FILTER(Dipromats!H$3:H$101, REGEXMATCH(Dipromats!$A$3:$A$101, ""(?i)"" & $A6) )"),0.483697863941618) -> 0.48369786 | H6: =IFERROR(__xludf.DUMMYFUNCTION("FILTER(Dipromats!I$3:I$101, REGEXMATCH(Dipromats!$A$3:$A$101, ""(?i)"" & $A6) )"),0.286129356930116) -> 0.28612936 | I6: =IFERROR(__xludf.DUMMYFUNCTION("FILTER(Dipromats!J$3:J$101, REGEXMATCH(Dipromats!$A$3:$A$101, ""(?i)"" & $A6) )"),0.29837198245895) -> 0.29837198 | M6: ONLY original_original
A7: delta_own_title | B7: =B3-B6 -> 0.013464335 | C7: =C3-C6 -> 0.012035666 | D7: =D3-D6 -> 0.036338152 | E7: =E3-E6 -> 0.033419673 | F7: =F3-F6 -> 0.045786463 | G7: =G3-G6 -> 0.015297133 | H7: =H3-H6 -> 0.047475789 | I7: =I3-I6 -> 0.069136852 | J7: =AVERAGE(B7:I7) -> 0.034119258 | L7: Number of models better than no_no | O7: =COUNTIF(B5:I5,"<0") + COUNTIF(B24:I24,"<0") + COUNTIF(B43:I43,"<0") + COUNTIF(B62:I62,"<0") -> 18
A8: gpt_title | B8: =IFERROR(__xludf.DUMMYFUNCTION("FILTER(Dipromats!C$3:C$101, REGEXMATCH(Dipromats!$A$3:$A$101, ""(?i)"" & $A8) )"),0.608500522443986) -> 0.60850052 | C8: =IFERROR(__xludf.DUMMYFUNCTION("FILTER(Dipromats!D$3:D$101, REGEXMATCH(Dipromats!$A$3:$A$101, ""(?i)"" & $A8) )"),0.565727300132339) -> 0.5657273 | D8: =IFERROR(__xludf.DUMMYFUNCTION("FILTER(Dipromats!E$3:E$101, REGEXMATCH(Dipromats!$A$3:$A$101, ""(?i)"" & $A8) )"),0.583927636565709) -> 0.58392764 | E8: =IFERROR(__xludf.DUMMYFUNCTION("FILTER(Dipromats!F$3:F$101, REGEXMATCH(Dipromats!$A$3:$A$101, ""(?i)"" & $A8) )"),0.523712547832867) -> 0.52371255 | F8: =IFERROR(__xludf.DUMMYFUNCTION("FILTER(Dipromats!G$3:G$101, REGEXMATCH(Dipromats!$A$3:$A$101, ""(?i)"" & $A8) )"),0.524902705155418) -> 0.52490271 | G8: =IFERROR(__xludf.DUMMYFUNCTION("FILTER(Dipromats!H$3:H$101, REGEXMATCH(Dipromats!$A$3:$A$101, ""(?i)"" & $A8) )"),0.490732657736496) -> 0.49073266 | H8: =IFERROR(__xludf.DUMMYFUNCTION("FILTER(Dipromats!I$3:I$101, REGEXMATCH(Dipromats!$A$3:$A$101, ""(?i)"" & $A8) )"),0.267289569310955) -> 0.26728957 | I8: =IFERROR(__xludf.DUMMYFUNCTION("FILTER(Dipromats!J$3:J$101, REGEXMATCH(Dipromats!$A$3:$A$101, ""(?i)"" & $A8) )"),0.297865824391553) -> 0.29786582 | L8: Number of models worse than no_no | O8: =COUNTIF(B5:I5,">0") + COUNTIF(B24:I24,">0") + COUNTIF(B43:I43,">0") + COUNTIF(B62:I62,">0") -> 14
A9: delta_gpt_title | B9: =B3-B8 -> 0.026004093 | C9: =C3-C8 -> 0.01766702 | D9: =D3-D8 -> 0.028619271 | E9: =E3-E8 -> 0.040981867 | F9: =F3-F8 -> 0.02703381 | G9: =G3-G8 -> 0.0082623397 | H9: =H3-H8 -> 0.066315577 | I9: =I3-I8 -> 0.06964301 | J9: =AVERAGE(B9:I9) -> 0.035565873 | L9: Percentage of better models | O9: =100*O7/(O7+O8) -> 56.25
A10: own_description | B10: =IFERROR(__xludf.DUMMYFUNCTION("FILTER(Dipromats!C$3:C$101, REGEXMATCH(Dipromats!$A$3:$A$101, ""(?i)"" & $A10), NOT(REGEXMATCH(Dipromats!$A$3:$A$101, ""(?i)complete"")) )"),0.631787462260468) -> 0.63178746 | C10: =IFERROR(__xludf.DUMMYFUNCTION("FILTER(Dipromats!D$3:D$101, REGEXMATCH(Dipromats!$A$3:$A$101, ""(?i)"" & $A10), NOT(REGEXMATCH(Dipromats!$A$3:$A$101, ""(?i)complete"")) )"),0.618216042484733) -> 0.61821604 | D10: =IFERROR(__xludf.DUMMYFUNCTION("FILTER(Dipromats!E$3:E$101, REGEXMATCH(Dipromats!$A$3:$A$101, ""(?i)"" & $A10), NOT(REGEXMATCH(Dipromats!$A$3:$A$101, ""(?i)complete"")) )"),0.586439666342686) -> 0.58643967 | E10: =IFERROR(__xludf.DUMMYFUNCTION("FILTER(Dipromats!F$3:F$101, REGEXMATCH(Dipromats!$A$3:$A$101, ""(?i)"" & $A10), NOT(REGEXMATCH(Dipromats!$A$3:$A$101, ""(?i)complete"")) )"),0.569895182181278) -> 0.56989518 | F10: =IFERROR(__xludf.DUMMYFUNCTION("FILTER(Dipromats!G$3:G$101, REGEXMATCH(Dipromats!$A$3:$A$101, ""(?i)"" & $A10), NOT(REGEXMATCH(Dipromats!$A$3:$A$101, ""(?i)complete"")) )"),0.546258468663482) -> 0.54625847 | G10: =IFERROR(__xludf.DUMMYFUNCTION("FILTER(Dipromats!H$3:H$101, REGEXMATCH(Dipromats!$A$3:$A$101, ""(?i)"" & $A10), NOT(REGEXMATCH(Dipromats!$A$3:$A$101, ""(?i)complete"")) )"),0.512012998082786) -> 0.512013 | H10: =IFERROR(__xludf.DUMMYFUNCTION("FILTER(Dipromats!I$3:I$101, REGEXMATCH(Dipromats!$A$3:$A$101, ""(?i)"" & $A10), NOT(REGEXMATCH(Dipromats!$A$3:$A$101, ""(?i)complete"")) )"),0.288938661231155) -> 0.28893866 | I10: =IFERROR(__xludf.DUMMYFUNCTION("FILTER(Dipromats!J$3:J$101, REGEXMATCH(Dipromats!$A$3:$A$101, ""(?i)"" & $A10), NOT(REGEXMATCH(Dipromats!$A$3:$A$101, ""(?i)complete"")) )"),0.329512617172151) -> 0.32951262 | L10: Percentage of worst models | O10: =100*O8/(O7+O8) -> 43.75
A11: delta_own_description | B11: =B3-B10 -> 0.002717153 | C11: =C3-C10 -> -0.034821722 | D11: =D3-D10 -> 0.026107241 | E11: =E3-E10 -> -0.0052007674 | F11: =F3-F10 -> 0.0056780461 | G11: =G3-G10 -> -0.013018001 | H11: =H3-H10 -> 0.044666485 | I11: =I3-I10 -> 0.037996218 | J11: =AVERAGE(B11:I11) -> 0.0080155816
A12: gpt_description | B12: =IFERROR(__xludf.DUMMYFUNCTION("FILTER(Dipromats!C$3:C$101, REGEXMATCH(Dipromats!$A$3:$A$101, ""(?i)"" & $A12), NOT(REGEXMATCH(Dipromats!$A$3:$A$101, ""(?i)complete"")) )"),0.640317661477475) -> 0.64031766 | C12: =IFERROR(__xludf.DUMMYFUNCTION("FILTER(Dipromats!D$3:D$101, REGEXMATCH(Dipromats!$A$3:$A$101, ""(?i)"" & $A12), NOT(REGEXMATCH(Dipromats!$A$3:$A$101, ""(?i)complete"")) )"),0.61354665612827) -> 0.61354666 | D12: =IFERROR(__xludf.DUMMYFUNCTION("FILTER(Dipromats!E$3:E$101, REGEXMATCH(Dipromats!$A$3:$A$101, ""(?i)"" & $A12), NOT(REGEXMATCH(Dipromats!$A$3:$A$101, ""(?i)complete"")) )"),0.613750839783722) -> 0.61375084 | E12: =IFERROR(__xludf.DUMMYFUNCTION("FILTER(Dipromats!F$3:F$101, REGEXMATCH(Dipromats!$A$3:$A$101, ""(?i)"" & $A12), NOT(REGEXMATCH(Dipromats!$A$3:$A$101, ""(?i)complete"")) )"),0.578681917130575) -> 0.57868192 | F12: =IFERROR(__xludf.DUMMYFUNCTION("FILTER(Dipromats!G$3:G$101, REGEXMATCH(Dipromats!$A$3:$A$101, ""(?i)"" & $A12), NOT(REGEXMATCH(Dipromats!$A$3:$A$101, ""(?i)complete"")) )"),0.545763744390765) -> 0.54576374 | G12: =IFERROR(__xludf.DUMMYFUNCTION("FILTER(Dipromats!H$3:H$101, REGEXMATCH(Dipromats!$A$3:$A$101, ""(?i)"" & $A12), NOT(REGEXMATCH(Dipromats!$A$3:$A$101, ""(?i)complete"")) )"),0.524262991587101) -> 0.52426299 | H12: =IFERROR(__xludf.DUMMYFUNCTION("FILTER(Dipromats!I$3:I$101, REGEXMATCH(Dipromats!$A$3:$A$101, ""(?i)"" & $A12), NOT(REGEXMATCH(Dipromats!$A$3:$A$101, ""(?i)complete"")) )"),0.284838731621514) -> 0.28483873 | I12: =IFERROR(__xludf.DUMMYFUNCTION("FILTER(Dipromats!J$3:J$101, REGEXMATCH(Dipromats!$A$3:$A$101, ""(?i)"" & $A12), NOT(REGEXMATCH(Dipromats!$A$3:$A$101, ""(?i)complete"")) )"),0.300772443809359) -> 0.30077244 | M12: Enhanced Desc Only
A13: delta_gpt_description | B13: =B3-B12 -> -0.0058130462 | C13: =C3-C12 -> -0.030152336 | D13: =D3-D12 -> -0.0012039321 | E13: =E3-E12 -> -0.013987502 | F13: =F3-F12 -> 0.0061727703 | G13: =G3-G12 -> -0.025267994 | H13: =H3-H12 -> 0.048766415 | I13: =I3-I12 -> 0.066736391 | J13: =AVERAGE(B13:I13) -> 0.0056563456 | L13: Number of models better than no_no | O13: =COUNTIF(B7:I7,"<0") + COUNTIF(B9:I9,"<0") + COUNTIF(B11:I11,"<0") + COUNTIF(B13:I13,"<0") + COUNTIF(B15:I15,"<0") + COUNTIF(B17:I17,"<0") + COUNTIF(B26:I26,"<0") + COUNTIF(B28:I28,"<0") + COUNTIF(B30:I30,"<0") + COUNTIF(B32:I32,"<0") + COUNTIF(B34:I34,"<0") + COUNTIF(B36:I36,"<0") + COUNTIF(B45:I45,"<0") + COUNTIF(B47:I47,"<0") + COUNTIF(B49:I49,"<0") + COUNTIF(B51:I51,"<0") + COUNTIF(B53:I53,"<0") + COUNTIF(B55:I55,"<0") + COUNTIF(B64:I64,"<0") + COUNTIF(B66:I66,"<0") + COUNTIF(B68:I68,"<0") + COUNTIF(B69:I69,"<0") + COUNTIF(B70:I70,"<0") + COUNTIF(B72:I72,"<0") + COUNTIF(B74:I74,"<0") -> 44
A14: own_description_complete | B14: =IFERROR(__xludf.DUMMYFUNCTION("FILTER(Dipromats!C$3:C$101, REGEXMATCH(Dipromats!$A$3:$A$101, ""(?i)"" & $A14) )"),0.632355163340107) -> 0.63235516 | C14: =IFERROR(__xludf.DUMMYFUNCTION("FILTER(Dipromats!D$3:D$101, REGEXMATCH(Dipromats!$A$3:$A$101, ""(?i)"" & $A14) )"),0.606225827187698) -> 0.60622583 | D14: =IFERROR(__xludf.DUMMYFUNCTION("FILTER(Dipromats!E$3:E$101, REGEXMATCH(Dipromats!$A$3:$A$101, ""(?i)"" & $A14) )"),0.535090217689681) -> 0.53509022 | E14: =IFERROR(__xludf.DUMMYFUNCTION("FILTER(Dipromats!F$3:F$101, REGEXMATCH(Dipromats!$A$3:$A$101, ""(?i)"" & $A14) )"),0.477750371254548) -> 0.47775037 | F14: =IFERROR(__xludf.DUMMYFUNCTION("FILTER(Dipromats!G$3:G$101, REGEXMATCH(Dipromats!$A$3:$A$101, ""(?i)"" & $A14) )"),0.457442229094388) -> 0.45744223 | G14: =IFERROR(__xludf.DUMMYFUNCTION("FILTER(Dipromats!H$3:H$101, REGEXMATCH(Dipromats!$A$3:$A$101, ""(?i)"" & $A14) )"),0.427462251024684) -> 0.42746225 | H14: =IFERROR(__xludf.DUMMYFUNCTION("FILTER(Dipromats!I$3:I$101, REGEXMATCH(Dipromats!$A$3:$A$101, ""(?i)"" & $A14) )"),0.245367655632764) -> 0.24536766 | I14: =IFERROR(__xludf.DUMMYFUNCTION("FILTER(Dipromats!J$3:J$101, REGEXMATCH(Dipromats!$A$3:$A$101, ""(?i)"" & $A14) )"),0.282654794342775) -> 0.28265479 | L14: Number of models worse than no_no | O14: =COUNTIF(B7:I7,">0") + COUNTIF(B9:I9,">0") + COUNTIF(B11:I11,">0") + COUNTIF(B13:I13,">0") + COUNTIF(B15:I15,">0") + COUNTIF(B17:I17,">0") + COUNTIF(B26:I26,">0") + COUNTIF(B28:I28,">0") + COUNTIF(B30:I30,">0") + COUNTIF(B32:I32,">0") + COUNTIF(B34:I34,">0") + COUNTIF(B36:I36,">0") + COUNTIF(B45:I45,">0") + COUNTIF(B47:I47,">0") + COUNTIF(B49:I49,">0") + COUNTIF(B51:I51,">0") + COUNTIF(B53:I53,">0") + COUNTIF(B55:I55,">0") + COUNTIF(B64:I64,">0") + COUNTIF(B66:I66,">0") + COUNTIF(B68:I68,">0") + COUNTIF(B69:I69,">0") + COUNTIF(B70:I70,">0") + COUNTIF(B72:I72,">0") + COUNTIF(B74:I74,">0") -> 142
A15: delta_own_description_comp | B15: =B3-B14 -> 0.0021494519 | C15: =C3-C14 -> -0.022831507 | D15: =D3-D14 -> 0.07745669 | E15: =E3-E14 -> 0.086944043 | F15: =F3-F14 -> 0.094494286 | G15: =G3-G14 -> 0.071532746 | H15: =H3-H14 -> 0.088237491 | I15: =I3-I14 -> 0.08485404 | J15: =AVERAGE(B15:I15) -> 0.060354655 | L15: Percentage of better models | O15: =O13*100/(44+142) -> 23.655914
A16: gpt_description_complete | B16: =IFERROR(__xludf.DUMMYFUNCTION("FILTER(Dipromats!C$3:C$101, REGEXMATCH(Dipromats!$A$3:$A$101, ""(?i)"" & $A16) )"),0.626620634285161) -> 0.62662063 | C16: =IFERROR(__xludf.DUMMYFUNCTION("FILTER(Dipromats!D$3:D$101, REGEXMATCH(Dipromats!$A$3:$A$101, ""(?i)"" & $A16) )"),0.604801060798369) -> 0.60480106 | D16: =IFERROR(__xludf.DUMMYFUNCTION("FILTER(Dipromats!E$3:E$101, REGEXMATCH(Dipromats!$A$3:$A$101, ""(?i)"" & $A16) )"),0.274748595417237) -> 0.2747486 | E16: =IFERROR(__xludf.DUMMYFUNCTION("FILTER(Dipromats!F$3:F$101, REGEXMATCH(Dipromats!$A$3:$A$101, ""(?i)"" & $A16) )"),0.380177808740426) -> 0.38017781 | F16: =IFERROR(__xludf.DUMMYFUNCTION("FILTER(Dipromats!G$3:G$101, REGEXMATCH(Dipromats!$A$3:$A$101, ""(?i)"" & $A16) )"),0.484593915089339) -> 0.48459392 | G16: =IFERROR(__xludf.DUMMYFUNCTION("FILTER(Dipromats!H$3:H$101, REGEXMATCH(Dipromats!$A$3:$A$101, ""(?i)"" & $A16) )"),0.437797137788191) -> 0.43779714 | H16: =IFERROR(__xludf.DUMMYFUNCTION("FILTER(Dipromats!I$3:I$101, REGEXMATCH(Dipromats!$A$3:$A$101, ""(?i)"" & $A16) )"),0.220620940157727) -> 0.22062094 | I16: =IFERROR(__xludf.DUMMYFUNCTION("FILTER(Dipromats!J$3:J$101, REGEXMATCH(Dipromats!$A$3:$A$101, ""(?i)"" & $A16) )"),0.271705614091627) -> 0.27170561 | L16: Percentage of worst models | O16: =O14*100/(44+142) -> 76.344086
A17: delta_gpt_description_comp | B17: =B3-B16 -> 0.007883981 | C17: =C3-C16 -> -0.021406741 | D17: =D3-D16 -> 0.33779831 | E17: =E3-E16 -> 0.18451661 | F17: =F3-F16 -> 0.0673426 | G17: =G3-G16 -> 0.06119786 | H17: =H3-H16 -> 0.11298421 | I17: =I3-I16 -> 0.095803221 | J17: =AVERAGE(B17:I17) -> 0.10576501
B18: =AVERAGE(B5,B7,B9,B11,B13,B15,B17) -> 0.0060365386 | C18: =AVERAGE(C5,C7,C9,C11,C13,C15,C17) -> -0.015654013 | D18: =AVERAGE(D5,D7,D9,D11,D13,D15,D17) -> 0.070498216 | E18: =AVERAGE(E5,E7,E9,E11,E13,E15,E17) -> 0.042592143 | F18: =AVERAGE(F5,F7,F9,F11,F13,F15,F17) -> 0.032280863 | G18: =AVERAGE(G5,G7,G9,G11,G13,G15,G17) -> 0.011747597 | H18: =AVERAGE(H5,H7,H9,H11,H13,H15,H17) -> 0.058117953 | I18: =AVERAGE(I5,I7,I9,I11,I13,I15,I17) -> 0.062730138
B19: =AVERAGE(B18,C18) -> -0.0048087372 | D19: =AVERAGE(D18,E18) -> 0.05654518 | F19: =AVERAGE(F18,G18) -> 0.02201423 | H19: =AVERAGE(H18,I18) -> 0.060424045
A21: 3_steps | B21: calme | D21: gemma | F21: exaone | H21: granite
A22: no_no | B22: =IFERROR(__xludf.DUMMYFUNCTION("FILTER(SemEval_2025_T2!$G$3:$G$100, REGEXMATCH(SemEval_2025_T2!$A$3:$A$100, ""(?i)"" & $B$21 &""_"" & $A22) )"),0.4296) -> 0.4296 | C22: =IFERROR(__xludf.DUMMYFUNCTION("FILTER(SemEval_2025_T2!$H$3:$H$100, REGEXMATCH(SemEval_2025_T2!$A$3:$A$100, ""(?i)"" & $B$21 &""_"" & $A22) )"),0.2824) -> 0.2824 | D22: =IFERROR(__xludf.DUMMYFUNCTION("FILTER(SemEval_2025_T2!$G$3:$G$100, REGEXMATCH(SemEval_2025_T2!$A$3:$A$100, ""(?i)"" & $D$21 &""_"" & $A22) )"),0.4004) -> 0.4004 | E22: =IFERROR(__xludf.DUMMYFUNCTION("FILTER(SemEval_2025_T2!$H$3:$H$100, REGEXMATCH(SemEval_2025_T2!$A$3:$A$100, ""(?i)"" & $D$21 &""_"" & $A22) )"),0.264) -> 0.264 | F22: =IFERROR(__xludf.DUMMYFUNCTION("FILTER(SemEval_2025_T2!$G$3:$G$100, REGEXMATCH(SemEval_2025_T2!$A$3:$A$100, ""(?i)"" & $F$21 &""_"" & $A22) )"),0.3482) -> 0.3482 | G22: =IFERROR(__xludf.DUMMYFUNCTION("FILTER(SemEval_2025_T2!$H$3:$H$100, REGEXMATCH(SemEval_2025_T2!$A$3:$A$100, ""(?i)"" & $F$21 &""_"" & $A22) )"),0.2128) -> 0.2128 | H22: =IFERROR(__xludf.DUMMYFUNCTION("FILTER(SemEval_2025_T2!$G$3:$G$100, REGEXMATCH(SemEval_2025_T2!$A$3:$A$100, ""(?i)"" & $H$21 &""_"" & $A22) )"),0.179199999999999) -> 0.1792 | I22: =IFERROR(__xludf.DUMMYFUNCTION("FILTER(SemEval_2025_T2!$H$3:$H$100, REGEXMATCH(SemEval_2025_T2!$A$3:$A$100, ""(?i)"" & $H$21 &""_"" & $A22) )"),0.1202) -> 0.1202
A23: original_original | B23: =IFERROR(__xludf.DUMMYFUNCTION("FILTER(SemEval_2025_T2!$G$3:$G$100, REGEXMATCH(SemEval_2025_T2!$A$3:$A$100, ""(?i)"" & $B$21 &""_"" & $A23) )"),0.4884) -> 0.4884 | C23: =IFERROR(__xludf.DUMMYFUNCTION("FILTER(SemEval_2025_T2!$H$3:$H$100, REGEXMATCH(SemEval_2025_T2!$A$3:$A$100, ""(?i)"" & $B$21 &""_"" & $A23) )"),0.309799999999999) -> 0.3098 | D23: =IFERROR(__xludf.DUMMYFUNCTION("FILTER(SemEval_2025_T2!$G$3:$G$100, REGEXMATCH(SemEval_2025_T2!$A$3:$A$100, ""(?i)"" & $D$21 &""_"" & $A23) )"),0.4214) -> 0.4214 | E23: =IFERROR(__xludf.DUMMYFUNCTION("FILTER(SemEval_2025_T2!$H$3:$H$100, REGEXMATCH(SemEval_2025_T2!$A$3:$A$100, ""(?i)"" & $D$21 &""_"" & $A23) )"),0.2862) -> 0.2862 | F23: =IFERROR(__xludf.DUMMYFUNCTION("FILTER(SemEval_2025_T2!$G$3:$G$100, REGEXMATCH(SemEval_2025_T2!$A$3:$A$100, ""(?i)"" & $F$21 &""_"" & $A23) )"),0.3434) -> 0.3434 | G23: =IFERROR(__xludf.DUMMYFUNCTION("FILTER(SemEval_2025_T2!$H$3:$H$100, REGEXMATCH(SemEval_2025_T2!$A$3:$A$100, ""(?i)"" & $F$21 &""_"" & $A23) )"),0.2124) -> 0.2124 | H23: =IFERROR(__xludf.DUMMYFUNCTION("FILTER(SemEval_2025_T2!$G$3:$G$100, REGEXMATCH(SemEval_2025_T2!$A$3:$A$100, ""(?i)"" & $H$21 &""_"" & $A23) )"),0.1666) -> 0.1666 | I23: =IFERROR(__xludf.DUMMYFUNCTION("FILTER(SemEval_2025_T2!$H$3:$H$100, REGEXMATCH(SemEval_2025_T2!$A$3:$A$100, ""(?i)"" & $H$21 &""_"" & $A23) )"),0.1056) -> 0.1056
A24: delta_original | B24: =B22-B23 -> -0.0588 | C24: =C22-C23 -> -0.0274 | D24: =D22-D23 -> -0.021 | E24: =E22-E23 -> -0.0222 | F24: =F22-F23 -> 0.0048 | G24: =G22-G23 -> 0.0004 | H24: =H22-H23 -> 0.0126 | I24: =I22-I23 -> 0.0146 | J24: =AVERAGE(B24,D24,F24,H24) -> -0.0156 | K24: =AVERAGE(C24,E24,G24,I24) -> -0.00865 | L24: =AVERAGE(J24,K24) -> -0.012125
A25: only_title | B25: =IFERROR(__xludf.DUMMYFUNCTION("FILTER(SemEval_2025_T2!$G$3:$G$100, REGEXMATCH(SemEval_2025_T2!$A$3:$A$100, ""(?i)"" & $B$21 &""_"" & $A25) )"),0.4362) -> 0.4362 | C25: =IFERROR(__xludf.DUMMYFUNCTION("FILTER(SemEval_2025_T2!$H$3:$H$100, REGEXMATCH(SemEval_2025_T2!$A$3:$A$100, ""(?i)"" & $B$21 &""_"" & $A25) )"),0.3042) -> 0.3042 | D25: =IFERROR(__xludf.DUMMYFUNCTION("FILTER(SemEval_2025_T2!$G$3:$G$100, REGEXMATCH(SemEval_2025_T2!$A$3:$A$100, ""(?i)"" & $D$21 &""_"" & $A25) )"),0.3392) -> 0.3392 | E25: =IFERROR(__xludf.DUMMYFUNCTION("FILTER(SemEval_2025_T2!$H$3:$H$100, REGEXMATCH(SemEval_2025_T2!$A$3:$A$100, ""(?i)"" & $D$21 &""_"" & $A25) )"),0.2208) -> 0.2208 | F25: =IFERROR(__xludf.DUMMYFUNCTION("FILTER(SemEval_2025_T2!$G$3:$G$100, REGEXMATCH(SemEval_2025_T2!$A$3:$A$100, ""(?i)"" & $F$21 &""_"" & $A25) )"),0.3016) -> 0.3016 | G25: =IFERROR(__xludf.DUMMYFUNCTION("FILTER(SemEval_2025_T2!$H$3:$H$100, REGEXMATCH(SemEval_2025_T2!$A$3:$A$100, ""(?i)"" & $F$21 &""_"" & $A25) )"),0.1792) -> 0.1792 | H25: =IFERROR(__xludf.DUMMYFUNCTION("FILTER(SemEval_2025_T2!$G$3:$G$100, REGEXMATCH(SemEval_2025_T2!$A$3:$A$100, ""(?i)"" & $H$21 &""_"" & $A25) )"),0.1424) -> 0.1424 | I25: =IFERROR(__xludf.DUMMYFUNCTION("FILTER(SemEval_2025_T2!$H$3:$H$100, REGEXMATCH(SemEval_2025_T2!$A$3:$A$100, ""(?i)"" & $H$21 &""_"" & $A25) )"),0.0802) -> 0.0802
A26: delta_own_title | B26: =B22-B25 -> -0.0066 | C26: =C22-C25 -> -0.0218 | D26: =D22-D25 -> 0.0612 | E26: =E22-E25 -> 0.0432 | F26: =F22-F25 -> 0.0466 | G26: =G22-G25 -> 0.0336 | H26: =H22-H25 -> 0.0368 | I26: =I22-I25 -> 0.04 | J26: =AVERAGE(B26,D26,F26,H26) -> 0.0345 | K26: =AVERAGE(C26,E26,G26,I26) -> 0.02375 | L26: =AVERAGE(J26,K26) -> 0.029125
A27: gpt_only_title | B27: =IFERROR(__xludf.DUMMYFUNCTION("FILTER(SemEval_2025_T2!$G$3:$G$100, REGEXMATCH(SemEval_2025_T2!$A$3:$A$100, ""(?i)"" & $B$21 &""_"" & $A27) )"),0.444199999999999) -> 0.4442 | C27: =IFERROR(__xludf.DUMMYFUNCTION("FILTER(SemEval_2025_T2!$H$3:$H$100, REGEXMATCH(SemEval_2025_T2!$A$3:$A$100, ""(?i)"" & $B$21 &""_"" & $A27) )"),0.281) -> 0.281 | D27: =IFERROR(__xludf.DUMMYFUNCTION("FILTER(SemEval_2025_T2!$G$3:$G$100, REGEXMATCH(SemEval_2025_T2!$A$3:$A$100, ""(?i)"" & $D$21 &""_"" & $A27) )"),0.3556) -> 0.3556 | E27: =IFERROR(__xludf.DUMMYFUNCTION("FILTER(SemEval_2025_T2!$H$3:$H$100, REGEXMATCH(SemEval_2025_T2!$A$3:$A$100, ""(?i)"" & $D$21 &""_"" & $A27) )"),0.235) -> 0.235 | F27: =IFERROR(__xludf.DUMMYFUNCTION("FILTER(SemEval_2025_T2!$G$3:$G$100, REGEXMATCH(SemEval_2025_T2!$A$3:$A$100, ""(?i)"" & $F$21 &""_"" & $A27) )"),0.2892) -> 0.2892 | G27: =IFERROR(__xludf.DUMMYFUNCTION("FILTER(SemEval_2025_T2!$H$3:$H$100, REGEXMATCH(SemEval_2025_T2!$A$3:$A$100, ""(?i)"" & $F$21 &""_"" & $A27) )"),0.16) -> 0.16 | H27: =IFERROR(__xludf.DUMMYFUNCTION("FILTER(SemEval_2025_T2!$G$3:$G$100, REGEXMATCH(SemEval_2025_T2!$A$3:$A$100, ""(?i)"" & $H$21 &""_"" & $A27) )"),0.1274) -> 0.1274 | I27: =IFERROR(__xludf.DUMMYFUNCTION("FILTER(SemEval_2025_T2!$H$3:$H$100, REGEXMATCH(SemEval_2025_T2!$A$3:$A$100, ""(?i)"" & $H$21 &""_"" & $A27) )"),0.0496) -> 0.0496
A28: delta_gpt_title | B28: =B22-B27 -> -0.0146 | C28: =C22-C27 -> 0.0014 | D28: =D22-D27 -> 0.0448 | E28: =E22-E27 -> 0.029 | F28: =F22-F27 -> 0.059 | G28: =G22-G27 -> 0.0528 | H28: =H22-H27 -> 0.0518 | I28: =I22-I27 -> 0.0706 | J28: =AVERAGE(B28,D28,F28,H28) -> 0.03525 | K28: =AVERAGE(C28,E28,G28,I28) -> 0.03845 | L28: =AVERAGE(J28,K28) -> 0.03685
A29: title_description | B29: =IFERROR(__xludf.DUMMYFUNCTION("FILTER(SemEval_2025_T2!$G$3:$G$100, REGEXMATCH(SemEval_2025_T2!$A$3:$A$100, ""(?i)"" & $B$21 &""_"" & $A29), NOT(REGEXMATCH(SemEval_2025_T2!$A$3:$A$100, ""(?i)complete"")) )"),0.4852) -> 0.4852 | C29: =IFERROR(__xludf.DUMMYFUNCTION("FILTER(SemEval_2025_T2!$H$3:$H$100, REGEXMATCH(SemEval_2025_T2!$A$3:$A$100, ""(?i)"" & $B$21 &""_"" & $A29), NOT(REGEXMATCH(SemEval_2025_T2!$A$3:$A$100, ""(?i)complete"")) )"),0.3286) -> 0.3286 | D29: =IFERROR(__xludf.DUMMYFUNCTION("FILTER(SemEval_2025_T2!$G$3:$G$100, REGEXMATCH(SemEval_2025_T2!$A$3:$A$100, ""(?i)"" & $D$21 &""_"" & $A29), NOT(REGEXMATCH(SemEval_2025_T2!$A$3:$A$100, ""(?i)complete"")) )"),0.3592) -> 0.3592 | E29: =IFERROR(__xludf.DUMMYFUNCTION("FILTER(SemEval_2025_T2!$H$3:$H$100, REGEXMATCH(SemEval_2025_T2!$A$3:$A$100, ""(?i)"" & $D$21 &""_"" & $A29), NOT(REGEXMATCH(SemEval_2025_T2!$A$3:$A$100, ""(?i)complete"")) )"),0.2508) -> 0.2508 | F29: =IFERROR(__xludf.DUMMYFUNCTION("FILTER(SemEval_2025_T2!$G$3:$G$100, REGEXMATCH(SemEval_2025_T2!$A$3:$A$100, ""(?i)"" & $F$21 &""_"" & $A29), NOT(REGEXMATCH(SemEval_2025_T2!$A$3:$A$100, ""(?i)complete"")) )"),0.3106) -> 0.3106 | G29: =IFERROR(__xludf.DUMMYFUNCTION("FILTER(SemEval_2025_T2!$H$3:$H$100, REGEXMATCH(SemEval_2025_T2!$A$3:$A$100, ""(?i)"" & $F$21 &""_"" & $A29), NOT(REGEXMATCH(SemEval_2025_T2!$A$3:$A$100, ""(?i)complete"")) )"),0.1764) -> 0.1764 | H29: =IFERROR(__xludf.DUMMYFUNCTION("FILTER(SemEval_2025_T2!$G$3:$G$100, REGEXMATCH(SemEval_2025_T2!$A$3:$A$100, ""(?i)"" & $H$21 &""_"" & $A29), NOT(REGEXMATCH(SemEval_2025_T2!$A$3:$A$100, ""(?i)complete"")) )"),0.1246) -> 0.1246 | I29: =IFERROR(__xludf.DUMMYFUNCTION("FILTER(SemEval_2025_T2!$H$3:$H$100, REGEXMATCH(SemEval_2025_T2!$A$3:$A$100, ""(?i)"" & $H$21 &""_"" & $A29), NOT(REGEXMATCH(SemEval_2025_T2!$A$3:$A$100, ""(?i)complete"")) )"),0.0576) -> 0.0576
A30: delta_own_description | B30: =B22-B29 -> -0.0556 | C30: =C22-C29 -> -0.0462 | D30: =D22-D29 -> 0.0412 | E30: =E22-E29 -> 0.0132 | F30: =F22-F29 -> 0.0376 | G30: =G22-G29 -> 0.0364 | H30: =H22-H29 -> 0.0546 | I30: =I22-I29 -> 0.0626 | J30: =AVERAGE(B30,D30,F30,H30) -> 0.01945 | K30: =AVERAGE(C30,E30,G30,I30) -> 0.0165 | L30: =AVERAGE(J30,K30) -> 0.017975
A31: gpt_title_description | B31: =IFERROR(__xludf.DUMMYFUNCTION("FILTER(SemEval_2025_T2!$G$3:$G$100, REGEXMATCH(SemEval_2025_T2!$A$3:$A$100, ""(?i)"" & $B$21 &""_"" & $A31), NOT(REGEXMATCH(SemEval_2025_T2!$A$3:$A$100, ""(?i)complete"")) )"),0.4684) -> 0.4684 | C31: =IFERROR(__xludf.DUMMYFUNCTION("FILTER(SemEval_2025_T2!$H$3:$H$100, REGEXMATCH(SemEval_2025_T2!$A$3:$A$100, ""(?i)"" & $B$21 &""_"" & $A31), NOT(REGEXMATCH(SemEval_2025_T2!$A$3:$A$100, ""(?i)complete"")) )"),0.3222) -> 0.3222 | D31: =IFERROR(__xludf.DUMMYFUNCTION("FILTER(SemEval_2025_T2!$G$3:$G$100, REGEXMATCH(SemEval_2025_T2!$A$3:$A$100, ""(?i)"" & $D$21 &""_"" & $A31), NOT(REGEXMATCH(SemEval_2025_T2!$A$3:$A$100, ""(?i)complete"")) )"),0.383) -> 0.383 | E31: =IFERROR(__xludf.DUMMYFUNCTION("FILTER(SemEval_2025_T2!$H$3:$H$100, REGEXMATCH(SemEval_2025_T2!$A$3:$A$100, ""(?i)"" & $D$21 &""_"" & $A31), NOT(REGEXMATCH(SemEval_2025_T2!$A$3:$A$100, ""(?i)complete"")) )"),0.267599999999999) -> 0.2676 | F31: =IFERROR(__xludf.DUMMYFUNCTION("FILTER(SemEval_2025_T2!$G$3:$G$100, REGEXMATCH(SemEval_2025_T2!$A$3:$A$100, ""(?i)"" & $F$21 &""_"" & $A31), NOT(REGEXMATCH(SemEval_2025_T2!$A$3:$A$100, ""(?i)complete"")) )"),0.3124) -> 0.3124 | G31: =IFERROR(__xludf.DUMMYFUNCTION("FILTER(SemEval_2025_T2!$H$3:$H$100, REGEXMATCH(SemEval_2025_T2!$A$3:$A$100, ""(?i)"" & $F$21 &""_"" & $A31), NOT(REGEXMATCH(SemEval_2025_T2!$A$3:$A$100, ""(?i)complete"")) )"),0.177) -> 0.177 | H31: =IFERROR(__xludf.DUMMYFUNCTION("FILTER(SemEval_2025_T2!$G$3:$G$100, REGEXMATCH(SemEval_2025_T2!$A$3:$A$100, ""(?i)"" & $H$21 &""_"" & $A31), NOT(REGEXMATCH(SemEval_2025_T2!$A$3:$A$100, ""(?i)complete"")) )"),0.117799999999999) -> 0.1178 | I31: =IFERROR(__xludf.DUMMYFUNCTION("FILTER(SemEval_2025_T2!$H$3:$H$100, REGEXMATCH(SemEval_2025_T2!$A$3:$A$100, ""(?i)"" & $H$21 &""_"" & $A31), NOT(REGEXMATCH(SemEval_2025_T2!$A$3:$A$100, ""(?i)complete"")) )"),0.0406) -> 0.0406
A32: delta_gpt_description | B32: =B22-B31 -> -0.0388 | C32: =C22-C31 -> -0.0398 | D32: =D22-D31 -> 0.0174 | E32: =E22-E31 -> -0.0036 | F32: =F22-F31 -> 0.0358 | G32: =G22-G31 -> 0.0358 | H32: =H22-H31 -> 0.0614 | I32: =I22-I31 -> 0.0796 | J32: =AVERAGE(B32,D32,F32,H32) -> 0.01895 | K32: =AVERAGE(C32,E32,G32,I32) -> 0.018 | L32: =AVERAGE(J32,K32) -> 0.018475
A33: title_description_complete | B33: =IFERROR(__xludf.DUMMYFUNCTION("FILTER(SemEval_2025_T2!$G$3:$G$100, REGEXMATCH(SemEval_2025_T2!$A$3:$A$100, ""(?i)"" & $B$21 &""_"" & $A33) )"),0.4522) -> 0.4522 | C33: =IFERROR(__xludf.DUMMYFUNCTION("FILTER(SemEval_2025_T2!$H$3:$H$100, REGEXMATCH(SemEval_2025_T2!$A$3:$A$100, ""(?i)"" & $B$21 &""_"" & $A33) )"),0.3188) -> 0.3188 | D33: =IFERROR(__xludf.DUMMYFUNCTION("FILTER(SemEval_2025_T2!$G$3:$G$100, REGEXMATCH(SemEval_2025_T2!$A$3:$A$100, ""(?i)"" & $D$21 &""_"" & $A33) )"),0.281) -> 0.281 | E33: =IFERROR(__xludf.DUMMYFUNCTION("FILTER(SemEval_2025_T2!$H$3:$H$100, REGEXMATCH(SemEval_2025_T2!$A$3:$A$100, ""(?i)"" & $D$21 &""_"" & $A33) )"),0.281) -> 0.281 | F33: =IFERROR(__xludf.DUMMYFUNCTION("FILTER(SemEval_2025_T2!$G$3:$G$100, REGEXMATCH(SemEval_2025_T2!$A$3:$A$100, ""(?i)"" & $F$21 &""_"" & $A33) )"),0.2836) -> 0.2836 | G33: =IFERROR(__xludf.DUMMYFUNCTION("FILTER(SemEval_2025_T2!$H$3:$H$100, REGEXMATCH(SemEval_2025_T2!$A$3:$A$100, ""(?i)"" & $F$21 &""_"" & $A33) )"),0.189) -> 0.189 | H33: =IFERROR(__xludf.DUMMYFUNCTION("FILTER(SemEval_2025_T2!$G$3:$G$100, REGEXMATCH(SemEval_2025_T2!$A$3:$A$100, ""(?i)"" & $H$21 &""_"" & $A33) )"),0.1028) -> 0.1028 | I33: =IFERROR(__xludf.DUMMYFUNCTION("FILTER(SemEval_2025_T2!$H$3:$H$100, REGEXMATCH(SemEval_2025_T2!$A$3:$A$100, ""(?i)"" & $H$21 &""_"" & $A33) )"),0.0496) -> 0.0496
A34: delta_own_description_comp | B34: =B22-B33 -> -0.0226 | C34: =C22-C33 -> -0.0364 | D34: =D22-D33 -> 0.1194 | E34: =E22-E33 -> -0.017 | F34: =F22-F33 -> 0.0646 | G34: =G22-G33 -> 0.0238 | H34: =H22-H33 -> 0.0764 | I34: =I22-I33 -> 0.0706 | J34: =AVERAGE(B34,D34,F34,H34) -> 0.05945 | K34: =AVERAGE(C34,E34,G34,I34) -> 0.01025 | L34: =AVERAGE(J34,K34) -> 0.03485
A35: gpt_title_description_complete | B35: =IFERROR(__xludf.DUMMYFUNCTION("FILTER(SemEval_2025_T2!$G$3:$G$100, REGEXMATCH(SemEval_2025_T2!$A$3:$A$100, ""(?i)"" & $B$21 &""_"" & $A35) )"),0.453) -> 0.453 | C35: =IFERROR(__xludf.DUMMYFUNCTION("FILTER(SemEval_2025_T2!$H$3:$H$100, REGEXMATCH(SemEval_2025_T2!$A$3:$A$100, ""(?i)"" & $B$21 &""_"" & $A35) )"),0.3236) -> 0.3236 | D35: =IFERROR(__xludf.DUMMYFUNCTION("FILTER(SemEval_2025_T2!$G$3:$G$100, REGEXMATCH(SemEval_2025_T2!$A$3:$A$100, ""(?i)"" & $D$21 &""_"" & $A35) )"),0.2978) -> 0.2978 | E35: =IFERROR(__xludf.DUMMYFUNCTION("FILTER(SemEval_2025_T2!$H$3:$H$100, REGEXMATCH(SemEval_2025_T2!$A$3:$A$100, ""(?i)"" & $D$21 &""_"" & $A35) )"),0.211399999999999) -> 0.2114 | F35: =IFERROR(__xludf.DUMMYFUNCTION("FILTER(SemEval_2025_T2!$G$3:$G$100, REGEXMATCH(SemEval_2025_T2!$A$3:$A$100, ""(?i)"" & $F$21 &""_"" & $A35) )"),0.2526) -> 0.2526 | G35: =IFERROR(__xludf.DUMMYFUNCTION("FILTER(SemEval_2025_T2!$H$3:$H$100, REGEXMATCH(SemEval_2025_T2!$A$3:$A$100, ""(?i)"" & $F$21 &""_"" & $A35) )"),0.163) -> 0.163 | H35: =IFERROR(__xludf.DUMMYFUNCTION("FILTER(SemEval_2025_T2!$G$3:$G$100, REGEXMATCH(SemEval_2025_T2!$A$3:$A$100, ""(?i)"" & $H$21 &""_"" & $A35) )"),0.1008) -> 0.1008 | I35: =IFERROR(__xludf.DUMMYFUNCTION("FILTER(SemEval_2025_T2!$H$3:$H$100, REGEXMATCH(SemEval_2025_T2!$A$3:$A$100, ""(?i)"" & $H$21 &""_"" & $A35) )"),0.034) -> 0.034
A36: delta_gpt_description_comp | B36: =B22-B35 -> -0.0234 | C36: =C22-C35 -> -0.0412 | D36: =D22-D35 -> 0.1026 | E36: =E22-E35 -> 0.0526 | F36: =F22-F35 -> 0.0956 | G36: =G22-G35 -> 0.0498 | H36: =H22-H35 -> 0.0784 | I36: =I22-I35 -> 0.0862 | J36: =AVERAGE(B36,D36,F36,H36) -> 0.0633 | K36: =AVERAGE(C36,E36,G36,I36) -> 0.03685 | L36: =AVERAGE(J36,K36) -> 0.050075
B37: =AVERAGE(B24,B26,B28,B30,B32,B34,B36) -> -0.031485714 | C37: =AVERAGE(C24,C26,C28,C30,C32,C34,C36) -> -0.0302 | D37: =AVERAGE(D24,D26,D28,D30,D32,D34,D36) -> 0.052228571 | E37: =AVERAGE(E24,E26,E28,E30,E32,E34,E36) -> 0.0136 | F37: =AVERAGE(F24,F26,F28,F30,F32,F34,F36) -> 0.049142857 | G37: =AVERAGE(G24,G26,G28,G30,G32,G34,G36) -> 0.033228571 | H37: =AVERAGE(H24,H26,H28,H30,H32,H34,H36) -> 0.053142857 | I37: =AVERAGE(I24,I26,I28,I30,I32,I34,I36) -> 0.0606
B38: =AVERAGE(B37,C37) -> -0.030842857 | D38: =AVERAGE(D37,E37) -> 0.032914286 | F38: =AVERAGE(F37,G37) -> 0.041185714 | H38: =AVERAGE(H37,I37) -> 0.056871429
A40: hybrid | B40: calme | D40: gemma | F40: exaone | H40: granite
A41: no_no | B41: =IFERROR(__xludf.DUMMYFUNCTION("FILTER(SemEval_2025_T2!$E$3:$E$100, REGEXMATCH(SemEval_2025_T2!$A$3:$A$100, ""(?i)"" & $B$21 &""_"" & $A41) )"),0.5206) -> 0.5206 | C41: =IFERROR(__xludf.DUMMYFUNCTION("FILTER(SemEval_2025_T2!$F$3:$F$100, REGEXMATCH(SemEval_2025_T2!$A$3:$A$100, ""(?i)"" & $B$21 &""_"" & $A41) )"),0.3216) -> 0.3216 | D41: =IFERROR(__xludf.DUMMYFUNCTION("FILTER(SemEval_2025_T2!$E$3:$E$100, REGEXMATCH(SemEval_2025_T2!$A$3:$A$100, ""(?i)"" & $D$21 &""_"" & $A41) )"),0.289799999999999) -> 0.2898 | E41: =IFERROR(__xludf.DUMMYFUNCTION("FILTER(SemEval_2025_T2!$F$3:$F$100, REGEXMATCH(SemEval_2025_T2!$A$3:$A$100, ""(?i)"" & $D$21 &""_"" & $A41) )"),0.287799999999999) -> 0.2878 | F41: =IFERROR(__xludf.DUMMYFUNCTION("FILTER(SemEval_2025_T2!$E$3:$E$100, REGEXMATCH(SemEval_2025_T2!$A$3:$A$100, ""(?i)"" & $F$21 &""_"" & $A41) )"),0.363199999999999) -> 0.3632 | G41: =IFERROR(__xludf.DUMMYFUNCTION("FILTER(SemEval_2025_T2!$F$3:$F$100, REGEXMATCH(SemEval_2025_T2!$A$3:$A$100, ""(?i)"" & $F$21 &""_"" & $A41) )"),0.1464) -> 0.1464 | H41: =IFERROR(__xludf.DUMMYFUNCTION("FILTER(SemEval_2025_T2!$E$3:$E$100, REGEXMATCH(SemEval_2025_T2!$A$3:$A$100, ""(?i)"" & $H$21 &""_"" & $A41) )"),0.195) -> 0.195 | I41: =IFERROR(__xludf.DUMMYFUNCTION("FILTER(SemEval_2025_T2!$F$3:$F$100, REGEXMATCH(SemEval_2025_T2!$A$3:$A$100, ""(?i)"" & $H$21 &""_"" & $A41) )"),0.1172) -> 0.1172
A42: original_original | B42: =IFERROR(__xludf.DUMMYFUNCTION("FILTER(SemEval_2025_T2!$E$3:$E$100, REGEXMATCH(SemEval_2025_T2!$A$3:$A$100, ""(?i)"" & $B$21 &""_"" & $A42) )"),0.4858) -> 0.4858 | C42: =IFERROR(__xludf.DUMMYFUNCTION("FILTER(SemEval_2025_T2!$F$3:$F$100, REGEXMATCH(SemEval_2025_T2!$A$3:$A$100, ""(?i)"" & $B$21 &""_"" & $A42) )"),0.301799999999999) -> 0.3018 | D42: =IFERROR(__xludf.DUMMYFUNCTION("FILTER(SemEval_2025_T2!$E$3:$E$100, REGEXMATCH(SemEval_2025_T2!$A$3:$A$100, ""(?i)"" & $D$21 &""_"" & $A42) )"),0.4278) -> 0.4278 | E42: =IFERROR(__xludf.DUMMYFUNCTION("FILTER(SemEval_2025_T2!$F$3:$F$100, REGEXMATCH(SemEval_2025_T2!$A$3:$A$100, ""(?i)"" & $D$21 &""_"" & $A42) )"),0.324199999999999) -> 0.3242 | F42: =IFERROR(__xludf.DUMMYFUNCTION("FILTER(SemEval_2025_T2!$E$3:$E$100, REGEXMATCH(SemEval_2025_T2!$A$3:$A$100, ""(?i)"" & $F$21 &""_"" & $A42) )"),0.3398) -> 0.3398 | G42: =IFERROR(__xludf.DUMMYFUNCTION("FILTER(SemEval_2025_T2!$F$3:$F$100, REGEXMATCH(SemEval_2025_T2!$A$3:$A$100, ""(?i)"" & $F$21 &""_"" & $A42) )"),0.1402) -> 0.1402 | H42: =IFERROR(__xludf.DUMMYFUNCTION("FILTER(SemEval_2025_T2!$E$3:$E$100, REGEXMATCH(SemEval_2025_T2!$A$3:$A$100, ""(?i)"" & $H$21 &""_"" & $A42) )"),0.177) -> 0.177 | I42: =IFERROR(__xludf.DUMMYFUNCTION("FILTER(SemEval_2025_T2!$F$3:$F$100, REGEXMATCH(SemEval_2025_T2!$A$3:$A$100, ""(?i)"" & $H$21 &""_"" & $A42) )"),0.08) -> 0.08
...

Sheet RQ2
A1: RQ2 | B1: Is it better to use the original human defined descriptions of narratives or ask the models to rewrite / improve / extend them? | M1: ALL
A2: dipro | B2: calme | D2: gemma | F2: exaone | H2: granite | L2: Number of models better than original_original | O2: =COUNTIF(B5:I5,"<0") + COUNTIF(B7:I7,"<0") + COUNTIF(B9:I9,"<0") + COUNTIF(B11:I11,"<0") + COUNTIF(B13:I13,"<0") + COUNTIF(B15:I15,"<0") + COUNTIF(B22:I22,"<0") + COUNTIF(B24:I24,"<0") + COUNTIF(B26:I26,"<0") + COUNTIF(B28:I28,"<0") + COUNTIF(B30:I30,"<0") + COUNTIF(B32:I32,"<0") + COUNTIF(B39:I39,"<0") + COUNTIF(B41:I41,"<0") + COUNTIF(B43:I43,"<0") + COUNTIF(B45:I45,"<0") + COUNTIF(B47:I47,"<0") + COUNTIF(B49:I49,"<0") + COUNTIF(B56:I56,"<0") + COUNTIF(B58:I58,"<0") + COUNTIF(B60:I60,"<0") + COUNTIF(B61:I61,"<0") + COUNTIF(B62:I62,"<0") + COUNTIF(B64:I64,"<0") + COUNTIF(B66:I66,"<0") -> 24
A3: original_original | B3: =IFERROR(__xludf.DUMMYFUNCTION("FILTER(Dipromats!C$3:C$101, REGEXMATCH(Dipromats!$A$3:$A$101, ""(?i)"" & $A3) )"),0.638654812715595) -> 0.63865481 | C3: =IFERROR(__xludf.DUMMYFUNCTION("FILTER(Dipromats!D$3:D$101, REGEXMATCH(Dipromats!$A$3:$A$101, ""(?i)"" & $A3) )"),0.613462791622532) -> 0.61346279 | D3: =IFERROR(__xludf.DUMMYFUNCTION("FILTER(Dipromats!E$3:E$101, REGEXMATCH(Dipromats!$A$3:$A$101, ""(?i)"" & $A3) )"),0.624175131263906) -> 0.62417513 | E3: =IFERROR(__xludf.DUMMYFUNCTION("FILTER(Dipromats!F$3:F$101, REGEXMATCH(Dipromats!$A$3:$A$101, ""(?i)"" & $A3) )"),0.593223331315557) -> 0.59322333 | F3: =IFERROR(__xludf.DUMMYFUNCTION("FILTER(Dipromats!G$3:G$101, REGEXMATCH(Dipromats!$A$3:$A$101, ""(?i)"" & $A3) )"),0.572478446675392) -> 0.57247845 | G3: =IFERROR(__xludf.DUMMYFUNCTION("FILTER(Dipromats!H$3:H$101, REGEXMATCH(Dipromats!$A$3:$A$101, ""(?i)"" & $A3) )"),0.534765902917699) -> 0.5347659 | H3: =IFERROR(__xludf.DUMMYFUNCTION("FILTER(Dipromats!I$3:I$101, REGEXMATCH(Dipromats!$A$3:$A$101, ""(?i)"" & $A3) )"),0.335225441305954) -> 0.33522544 | I3: =IFERROR(__xludf.DUMMYFUNCTION("FILTER(Dipromats!J$3:J$101, REGEXMATCH(Dipromats!$A$3:$A$101, ""(?i)"" & $A3) )"),0.352567599779278) -> 0.3525676 | L3: Number of models worse than original_original | O3: =COUNTIF(B5:I5,">0") + COUNTIF(B7:I7,">0") + COUNTIF(B9:I9,">0") + COUNTIF(B11:I11,">0") + COUNTIF(B13:I13,">0") + COUNTIF(B15:I15,">0") + COUNTIF(B22:I22,">0") + COUNTIF(B24:I24,">0") + COUNTIF(B26:I26,">0") + COUNTIF(B28:I28,">0") + COUNTIF(B30:I30,">0") + COUNTIF(B32:I32,">0") + COUNTIF(B39:I39,">0") + COUNTIF(B41:I41,">0") + COUNTIF(B43:I43,">0") + COUNTIF(B45:I45,">0") + COUNTIF(B47:I47,">0") + COUNTIF(B49:I49,">0") + COUNTIF(B56:I56,">0") + COUNTIF(B58:I58,">0") + COUNTIF(B60:I60,">0") + COUNTIF(B61:I61,">0") + COUNTIF(B62:I62,">0") + COUNTIF(B64:I64,">0") + COUNTIF(B66:I66,">0") -> 162
A4: own_title | B4: =IFERROR(__xludf.DUMMYFUNCTION("FILTER(Dipromats!C$3:C$101, REGEXMATCH(Dipromats!$A$3:$A$101, ""(?i)"" & $A4) )"),0.621040280030557) -> 0.62104028 | C4: =IFERROR(__xludf.DUMMYFUNCTION("FILTER(Dipromats!D$3:D$101, REGEXMATCH(Dipromats!$A$3:$A$101, ""(?i)"" & $A4) )"),0.571358654012934) -> 0.57135865 | D4: =IFERROR(__xludf.DUMMYFUNCTION("FILTER(Dipromats!E$3:E$101, REGEXMATCH(Dipromats!$A$3:$A$101, ""(?i)"" & $A4) )"),0.57620875615112) -> 0.57620876 | E4: =IFERROR(__xludf.DUMMYFUNCTION("FILTER(Dipromats!F$3:F$101, REGEXMATCH(Dipromats!$A$3:$A$101, ""(?i)"" & $A4) )"),0.531274741257453) -> 0.53127474 | F4: =IFERROR(__xludf.DUMMYFUNCTION("FILTER(Dipromats!G$3:G$101, REGEXMATCH(Dipromats!$A$3:$A$101, ""(?i)"" & $A4) )"),0.506150051999198) -> 0.50615005 | G4: =IFERROR(__xludf.DUMMYFUNCTION("FILTER(Dipromats!H$3:H$101, REGEXMATCH(Dipromats!$A$3:$A$101, ""(?i)"" & $A4) )"),0.483697863941618) -> 0.48369786 | H4: =IFERROR(__xludf.DUMMYFUNCTION("FILTER(Dipromats!I$3:I$101, REGEXMATCH(Dipromats!$A$3:$A$101, ""(?i)"" & $A4) )"),0.286129356930116) -> 0.28612936 | I4: =IFERROR(__xludf.DUMMYFUNCTION("FILTER(Dipromats!J$3:J$101, REGEXMATCH(Dipromats!$A$3:$A$101, ""(?i)"" & $A4) )"),0.29837198245895) -> 0.29837198 | L4: Percentage of better models | O4: =100*O2/(O3+O2) -> 12.903226
A5: delta_own_title | B5: =B3-B4 -> 0.017614533 | C5: =C3-C4 -> 0.042104138 | D5: =D3-D4 -> 0.047966375 | E5: =E3-E4 -> 0.06194859 | F5: =F3-F4 -> 0.066328395 | G5: =G3-G4 -> 0.051068039 | H5: =H3-H4 -> 0.049096084 | I5: =I3-I4 -> 0.054195617 | J5: =AVERAGE(B5:I5) -> 0.048790221 | L5: Percentage of worst models | O5: =100*O3/(O2+O3) -> 87.096774
A6: gpt_title | B6: =IFERROR(__xludf.DUMMYFUNCTION("FILTER(Dipromats!C$3:C$101, REGEXMATCH(Dipromats!$A$3:$A$101, ""(?i)"" & $A6) )"),0.608500522443986) -> 0.60850052 | C6: =IFERROR(__xludf.DUMMYFUNCTION("FILTER(Dipromats!D$3:D$101, REGEXMATCH(Dipromats!$A$3:$A$101, ""(?i)"" & $A6) )"),0.565727300132339) -> 0.5657273 | D6: =IFERROR(__xludf.DUMMYFUNCTION("FILTER(Dipromats!E$3:E$101, REGEXMATCH(Dipromats!$A$3:$A$101, ""(?i)"" & $A6) )"),0.583927636565709) -> 0.58392764 | E6: =IFERROR(__xludf.DUMMYFUNCTION("FILTER(Dipromats!F$3:F$101, REGEXMATCH(Dipromats!$A$3:$A$101, ""(?i)"" & $A6) )"),0.523712547832867) -> 0.52371255 | F6: =IFERROR(__xludf.DUMMYFUNCTION("FILTER(Dipromats!G$3:G$101, REGEXMATCH(Dipromats!$A$3:$A$101, ""(?i)"" & $A6) )"),0.524902705155418) -> 0.52490271 | G6: =IFERROR(__xludf.DUMMYFUNCTION("FILTER(Dipromats!H$3:H$101, REGEXMATCH(Dipromats!$A$3:$A$101, ""(?i)"" & $A6) )"),0.490732657736496) -> 0.49073266 | H6: =IFERROR(__xludf.DUMMYFUNCTION("FILTER(Dipromats!I$3:I$101, REGEXMATCH(Dipromats!$A$3:$A$101, ""(?i)"" & $A6) )"),0.267289569310955) -> 0.26728957 | I6: =IFERROR(__xludf.DUMMYFUNCTION("FILTER(Dipromats!J$3:J$101, REGEXMATCH(Dipromats!$A$3:$A$101, ""(?i)"" & $A6) )"),0.297865824391553) -> 0.29786582
A7: delta_gpt_title | B7: =B3-B6 -> 0.03015429 | C7: =C3-C6 -> 0.047735491 | D7: =D3-D6 -> 0.040247495 | E7: =E3-E6 -> 0.069510783 | F7: =F3-F6 -> 0.047575742 | G7: =G3-G6 -> 0.044033245 | H7: =H3-H6 -> 0.067935872 | I7: =I3-I6 -> 0.054701775 | J7: =AVERAGE(B7:I7) -> 0.050236837
A8: own_description | B8: =IFERROR(__xludf.DUMMYFUNCTION("FILTER(Dipromats!C$3:C$101, REGEXMATCH(Dipromats!$A$3:$A$101, ""(?i)"" & $A8), NOT(REGEXMATCH(Dipromats!$A$3:$A$101, ""(?i)complete"")) )"),0.631787462260468) -> 0.63178746 | C8: =IFERROR(__xludf.DUMMYFUNCTION("FILTER(Dipromats!D$3:D$101, REGEXMATCH(Dipromats!$A$3:$A$101, ""(?i)"" & $A8), NOT(REGEXMATCH(Dipromats!$A$3:$A$101, ""(?i)complete"")) )"),0.618216042484733) -> 0.61821604 | D8: =IFERROR(__xludf.DUMMYFUNCTION("FILTER(Dipromats!E$3:E$101, REGEXMATCH(Dipromats!$A$3:$A$101, ""(?i)"" & $A8), NOT(REGEXMATCH(Dipromats!$A$3:$A$101, ""(?i)complete"")) )"),0.586439666342686) -> 0.58643967 | E8: =IFERROR(__xludf.DUMMYFUNCTION("FILTER(Dipromats!F$3:F$101, REGEXMATCH(Dipromats!$A$3:$A$101, ""(?i)"" & $A8), NOT(REGEXMATCH(Dipromats!$A$3:$A$101, ""(?i)complete"")) )"),0.569895182181278) -> 0.56989518 | F8: =IFERROR(__xludf.DUMMYFUNCTION("FILTER(Dipromats!G$3:G$101, REGEXMATCH(Dipromats!$A$3:$A$101, ""(?i)"" & $A8), NOT(REGEXMATCH(Dipromats!$A$3:$A$101, ""(?i)complete"")) )"),0.546258468663482) -> 0.54625847 | G8: =IFERROR(__xludf.DUMMYFUNCTION("FILTER(Dipromats!H$3:H$101, REGEXMATCH(Dipromats!$A$3:$A$101, ""(?i)"" & $A8), NOT(REGEXMATCH(Dipromats!$A$3:$A$101, ""(?i)complete"")) )"),0.512012998082786) -> 0.512013 | H8: =IFERROR(__xludf.DUMMYFUNCTION("FILTER(Dipromats!I$3:I$101, REGEXMATCH(Dipromats!$A$3:$A$101, ""(?i)"" & $A8), NOT(REGEXMATCH(Dipromats!$A$3:$A$101, ""(?i)complete"")) )"),0.288938661231155) -> 0.28893866 | I8: =IFERROR(__xludf.DUMMYFUNCTION("FILTER(Dipromats!J$3:J$101, REGEXMATCH(Dipromats!$A$3:$A$101, ""(?i)"" & $A8), NOT(REGEXMATCH(Dipromats!$A$3:$A$101, ""(?i)complete"")) )"),0.329512617172151) -> 0.32951262
A9: delta_own_description | B9: =B3-B8 -> 0.0068673505 | C9: =C3-C8 -> -0.0047532509 | D9: =D3-D8 -> 0.037735465 | E9: =E3-E8 -> 0.023328149 | F9: =F3-F8 -> 0.026219978 | G9: =G3-G8 -> 0.022752905 | H9: =H3-H8 -> 0.04628678 | I9: =I3-I8 -> 0.023054983 | J9: =AVERAGE(B9:I9) -> 0.022686545
A10: gpt_description | B10: =IFERROR(__xludf.DUMMYFUNCTION("FILTER(Dipromats!C$3:C$101, REGEXMATCH(Dipromats!$A$3:$A$101, ""(?i)"" & $A10), NOT(REGEXMATCH(Dipromats!$A$3:$A$101, ""(?i)complete"")) )"),0.640317661477475) -> 0.64031766 | C10: =IFERROR(__xludf.DUMMYFUNCTION("FILTER(Dipromats!D$3:D$101, REGEXMATCH(Dipromats!$A$3:$A$101, ""(?i)"" & $A10), NOT(REGEXMATCH(Dipromats!$A$3:$A$101, ""(?i)complete"")) )"),0.61354665612827) -> 0.61354666 | D10: =IFERROR(__xludf.DUMMYFUNCTION("FILTER(Dipromats!E$3:E$101, REGEXMATCH(Dipromats!$A$3:$A$101, ""(?i)"" & $A10), NOT(REGEXMATCH(Dipromats!$A$3:$A$101, ""(?i)complete"")) )"),0.613750839783722) -> 0.61375084 | E10: =IFERROR(__xludf.DUMMYFUNCTION("FILTER(Dipromats!F$3:F$101, REGEXMATCH(Dipromats!$A$3:$A$101, ""(?i)"" & $A10), NOT(REGEXMATCH(Dipromats!$A$3:$A$101, ""(?i)complete"")) )"),0.578681917130575) -> 0.57868192 | F10: =IFERROR(__xludf.DUMMYFUNCTION("FILTER(Dipromats!G$3:G$101, REGEXMATCH(Dipromats!$A$3:$A$101, ""(?i)"" & $A10), NOT(REGEXMATCH(Dipromats!$A$3:$A$101, ""(?i)complete"")) )"),0.545763744390765) -> 0.54576374 | G10: =IFERROR(__xludf.DUMMYFUNCTION("FILTER(Dipromats!H$3:H$101, REGEXMATCH(Dipromats!$A$3:$A$101, ""(?i)"" & $A10), NOT(REGEXMATCH(Dipromats!$A$3:$A$101, ""(?i)complete"")) )"),0.524262991587101) -> 0.52426299 | H10: =IFERROR(__xludf.DUMMYFUNCTION("FILTER(Dipromats!I$3:I$101, REGEXMATCH(Dipromats!$A$3:$A$101, ""(?i)"" & $A10), NOT(REGEXMATCH(Dipromats!$A$3:$A$101, ""(?i)complete"")) )"),0.284838731621514) -> 0.28483873 | I10: =IFERROR(__xludf.DUMMYFUNCTION("FILTER(Dipromats!J$3:J$101, REGEXMATCH(Dipromats!$A$3:$A$101, ""(?i)"" & $A10), NOT(REGEXMATCH(Dipromats!$A$3:$A$101, ""(?i)complete"")) )"),0.300772443809359) -> 0.30077244
A11: delta_gpt_description | B11: =B3-B10 -> -0.0016628488 | C11: =C3-C10 -> -8.3864506e-05 | D11: =D3-D10 -> 0.010424291 | E11: =E3-E10 -> 0.014541414 | F11: =F3-F10 -> 0.026714702 | G11: =G3-G10 -> 0.010502911 | H11: =H3-H10 -> 0.05038671 | I11: =I3-I10 -> 0.051795156 | J11: =AVERAGE(B11:I11) -> 0.020327309
A12: own_description_complete | B12: =IFERROR(__xludf.DUMMYFUNCTION("FILTER(Dipromats!C$3:C$101, REGEXMATCH(Dipromats!$A$3:$A$101, ""(?i)"" & $A12) )"),0.632355163340107) -> 0.63235516 | C12: =IFERROR(__xludf.DUMMYFUNCTION("FILTER(Dipromats!D$3:D$101, REGEXMATCH(Dipromats!$A$3:$A$101, ""(?i)"" & $A12) )"),0.606225827187698) -> 0.60622583 | D12: =IFERROR(__xludf.DUMMYFUNCTION("FILTER(Dipromats!E$3:E$101, REGEXMATCH(Dipromats!$A$3:$A$101, ""(?i)"" & $A12) )"),0.535090217689681) -> 0.53509022 | E12: =IFERROR(__xludf.DUMMYFUNCTION("FILTER(Dipromats!F$3:F$101, REGEXMATCH(Dipromats!$A$3:$A$101, ""(?i)"" & $A12) )"),0.477750371254548) -> 0.47775037 | F12: =IFERROR(__xludf.DUMMYFUNCTION("FILTER(Dipromats!G$3:G$101, REGEXMATCH(Dipromats!$A$3:$A$101, ""(?i)"" & $A12) )"),0.457442229094388) -> 0.45744223 | G12: =IFERROR(__xludf.DUMMYFUNCTION("FILTER(Dipromats!H$3:H$101, REGEXMATCH(Dipromats!$A$3:$A$101, ""(?i)"" & $A12) )"),0.427462251024684) -> 0.42746225 | H12: =IFERROR(__xludf.DUMMYFUNCTION("FILTER(Dipromats!I$3:I$101, REGEXMATCH(Dipromats!$A$3:$A$101, ""(?i)"" & $A12) )"),0.245367655632764) -> 0.24536766 | I12: =IFERROR(__xludf.DUMMYFUNCTION("FILTER(Dipromats!J$3:J$101, REGEXMATCH(Dipromats!$A$3:$A$101, ""(?i)"" & $A12) )"),0.282654794342775) -> 0.28265479
A13: delta_own_description_comp | B13: =B3-B12 -> 0.0062996494 | C13: =C3-C12 -> 0.0072369644 | D13: =D3-D12 -> 0.089084914 | E13: =E3-E12 -> 0.11547296 | F13: =F3-F12 -> 0.11503622 | G13: =G3-G12 -> 0.10730365 | H13: =H3-H12 -> 0.089857786 | I13: =I3-I12 -> 0.069912805 | J13: =AVERAGE(B13:I13) -> 0.075025619
A14: gpt_description_complete | B14: =IFERROR(__xludf.DUMMYFUNCTION("FILTER(Dipromats!C$3:C$101, REGEXMATCH(Dipromats!$A$3:$A$101, ""(?i)"" & $A14) )"),0.626620634285161) -> 0.62662063 | C14: =IFERROR(__xludf.DUMMYFUNCTION("FILTER(Dipromats!D$3:D$101, REGEXMATCH(Dipromats!$A$3:$A$101, ""(?i)"" & $A14) )"),0.604801060798369) -> 0.60480106 | D14: =IFERROR(__xludf.DUMMYFUNCTION("FILTER(Dipromats!E$3:E$101, REGEXMATCH(Dipromats!$A$3:$A$101, ""(?i)"" & $A14) )"),0.274748595417237) -> 0.2747486 | E14: =IFERROR(__xludf.DUMMYFUNCTION("FILTER(Dipromats!F$3:F$101, REGEXMATCH(Dipromats!$A$3:$A$101, ""(?i)"" & $A14) )"),0.380177808740426) -> 0.38017781 | F14: =IFERROR(__xludf.DUMMYFUNCTION("FILTER(Dipromats!G$3:G$101, REGEXMATCH(Dipromats!$A$3:$A$101, ""(?i)"" & $A14) )"),0.484593915089339) -> 0.48459392 | G14: =IFERROR(__xludf.DUMMYFUNCTION("FILTER(Dipromats!H$3:H$101, REGEXMATCH(Dipromats!$A$3:$A$101, ""(?i)"" & $A14) )"),0.437797137788191) -> 0.43779714 | H14: =IFERROR(__xludf.DUMMYFUNCTION("FILTER(Dipromats!I$3:I$101, REGEXMATCH(Dipromats!$A$3:$A$101, ""(?i)"" & $A14) )"),0.220620940157727) -> 0.22062094 | I14: =IFERROR(__xludf.DUMMYFUNCTION("FILTER(Dipromats!J$3:J$101, REGEXMATCH(Dipromats!$A$3:$A$101, ""(?i)"" & $A14) )"),0.271705614091627) -> 0.27170561
A15: delta_gpt_description_comp | B15: =B3-B14 -> 0.012034178 | C15: =C3-C14 -> 0.0086617308 | D15: =D3-D14 -> 0.34942654 | E15: =E3-E14 -> 0.21304552 | F15: =F3-F14 -> 0.087884532 | G15: =G3-G14 -> 0.096968765 | H15: =H3-H14 -> 0.1146045 | I15: =I3-I14 -> 0.080861986 | J15: =AVERAGE(B15:I15) -> 0.12043597
B16: =AVERAGE(B5,B7,B9,B11,B13,B15) -> 0.011884525 | C16: =AVERAGE(C5,C7,C9,C11,C13,C15) -> 0.016816868 | D16: =AVERAGE(D5,D7,D9,D11,D13,D15) -> 0.095814179 | E16: =AVERAGE(E5,E7,E9,E11,E13,E15) -> 0.08297457 | F16: =AVERAGE(F5,F7,F9,F11,F13,F15) -> 0.061626594 | G16: =AVERAGE(G5,G7,G9,G11,G13,G15) -> 0.055438253 | H16: =AVERAGE(H5,H7,H9,H11,H13,H15) -> 0.069694622 | I16: =AVERAGE(I5,I7,I9,I11,I13,I15) -> 0.05575372
B17: =AVERAGE(B16:C16) -> 0.014350697 | D17: =AVERAGE(D16:E16) -> 0.089394375 | F17: =AVERAGE(F16:G16) -> 0.058532424 | H17: =AVERAGE(H16:I16) -> 0.062724171
A19: 3_steps | B19: calme | D19: gemma | F19: exaone | H19: granite
A20: original_original | B20: =IFERROR(__xludf.DUMMYFUNCTION("FILTER(SemEval_2025_T2!$G$3:$G$100, REGEXMATCH(SemEval_2025_T2!$A$3:$A$100, ""(?i)"" & $B$19 &""_"" & $A20) )"),0.4884) -> 0.4884 | C20: =IFERROR(__xludf.DUMMYFUNCTION("FILTER(SemEval_2025_T2!$H$3:$H$100, REGEXMATCH(SemEval_2025_T2!$A$3:$A$100, ""(?i)"" & $B$19 &""_"" & $A20) )"),0.309799999999999) -> 0.3098 | D20: =IFERROR(__xludf.DUMMYFUNCTION("FILTER(SemEval_2025_T2!$G$3:$G$100, REGEXMATCH(SemEval_2025_T2!$A$3:$A$100, ""(?i)"" & $D$19 &""_"" & $A20) )"),0.4214) -> 0.4214 | E20: =IFERROR(__xludf.DUMMYFUNCTION("FILTER(SemEval_2025_T2!$H$3:$H$100, REGEXMATCH(SemEval_2025_T2!$A$3:$A$100, ""(?i)"" & $D$19 &""_"" & $A20) )"),0.2862) -> 0.2862 | F20: =IFERROR(__xludf.DUMMYFUNCTION("FILTER(SemEval_2025_T2!$G$3:$G$100, REGEXMATCH(SemEval_2025_T2!$A$3:$A$100, ""(?i)"" & $F$19 &""_"" & $A20) )"),0.3434) -> 0.3434 | G20: =IFERROR(__xludf.DUMMYFUNCTION("FILTER(SemEval_2025_T2!$H$3:$H$100, REGEXMATCH(SemEval_2025_T2!$A$3:$A$100, ""(?i)"" & $F$19 &""_"" & $A20) )"),0.2124) -> 0.2124 | H20: =IFERROR(__xludf.DUMMYFUNCTION("FILTER(SemEval_2025_T2!$G$3:$G$100, REGEXMATCH(SemEval_2025_T2!$A$3:$A$100, ""(?i)"" & $H$19 &""_"" & $A20) )"),0.1666) -> 0.1666 | I20: =IFERROR(__xludf.DUMMYFUNCTION("FILTER(SemEval_2025_T2!$H$3:$H$100, REGEXMATCH(SemEval_2025_T2!$A$3:$A$100, ""(?i)"" & $H$19 &""_"" & $A20) )"),0.1056) -> 0.1056
A21: only_title | B21: =IFERROR(__xludf.DUMMYFUNCTION("FILTER(SemEval_2025_T2!$G$3:$G$100, REGEXMATCH(SemEval_2025_T2!$A$3:$A$100, ""(?i)"" & $B$19 &""_"" & $A21) )"),0.4362) -> 0.4362 | C21: =IFERROR(__xludf.DUMMYFUNCTION("FILTER(SemEval_2025_T2!$H$3:$H$100, REGEXMATCH(SemEval_2025_T2!$A$3:$A$100, ""(?i)"" & $B$19 &""_"" & $A21) )"),0.3042) -> 0.3042 | D21: =IFERROR(__xludf.DUMMYFUNCTION("FILTER(SemEval_2025_T2!$G$3:$G$100, REGEXMATCH(SemEval_2025_T2!$A$3:$A$100, ""(?i)"" & $D$19 &""_"" & $A21) )"),0.3392) -> 0.3392 | E21: =IFERROR(__xludf.DUMMYFUNCTION("FILTER(SemEval_2025_T2!$H$3:$H$100, REGEXMATCH(SemEval_2025_T2!$A$3:$A$100, ""(?i)"" & $D$19 &""_"" & $A21) )"),0.2208) -> 0.2208 | F21: =IFERROR(__xludf.DUMMYFUNCTION("FILTER(SemEval_2025_T2!$G$3:$G$100, REGEXMATCH(SemEval_2025_T2!$A$3:$A$100, ""(?i)"" & $F$19 &""_"" & $A21) )"),0.3016) -> 0.3016 | G21: =IFERROR(__xludf.DUMMYFUNCTION("FILTER(SemEval_2025_T2!$H$3:$H$100, REGEXMATCH(SemEval_2025_T2!$A$3:$A$100, ""(?i)"" & $F$19 &""_"" & $A21) )"),0.1792) -> 0.1792 | H21: =IFERROR(__xludf.DUMMYFUNCTION("FILTER(SemEval_2025_T2!$G$3:$G$100, REGEXMATCH(SemEval_2025_T2!$A$3:$A$100, ""(?i)"" & $H$19 &""_"" & $A21) )"),0.1424) -> 0.1424 | I21: =IFERROR(__xludf.DUMMYFUNCTION("FILTER(SemEval_2025_T2!$H$3:$H$100, REGEXMATCH(SemEval_2025_T2!$A$3:$A$100, ""(?i)"" & $H$19 &""_"" & $A21) )"),0.0802) -> 0.0802
A22: delta_own_title | B22: =B20-B21 -> 0.0522 | C22: =C20-C21 -> 0.0056 | D22: =D20-D21 -> 0.0822 | E22: =E20-E21 -> 0.0654 | F22: =F20-F21 -> 0.0418 | G22: =G20-G21 -> 0.0332 | H22: =H20-H21 -> 0.0242 | I22: =I20-I21 -> 0.0254 | J22: =AVERAGE(B22,D22,F22,H22) -> 0.0501 | K22: =AVERAGE(C22,E22,G22,I22) -> 0.0324 | L22: =AVERAGE(J22,K22) -> 0.04125
A23: gpt_only_title | B23: =IFERROR(__xludf.DUMMYFUNCTION("FILTER(SemEval_2025_T2!$G$3:$G$100, REGEXMATCH(SemEval_2025_T2!$A$3:$A$100, ""(?i)"" & $B$19 &""_"" & $A23) )"),0.444199999999999) -> 0.4442 | C23: =IFERROR(__xludf.DUMMYFUNCTION("FILTER(SemEval_2025_T2!$H$3:$H$100, REGEXMATCH(SemEval_2025_T2!$A$3:$A$100, ""(?i)"" & $B$19 &""_"" & $A23) )"),0.281) -> 0.281 | D23: =IFERROR(__xludf.DUMMYFUNCTION("FILTER(SemEval_2025_T2!$G$3:$G$100, REGEXMATCH(SemEval_2025_T2!$A$3:$A$100, ""(?i)"" & $D$19 &""_"" & $A23) )"),0.3556) -> 0.3556 | E23: =IFERROR(__xludf.DUMMYFUNCTION("FILTER(SemEval_2025_T2!$H$3:$H$100, REGEXMATCH(SemEval_2025_T2!$A$3:$A$100, ""(?i)"" & $D$19 &""_"" & $A23) )"),0.235) -> 0.235 | F23: =IFERROR(__xludf.DUMMYFUNCTION("FILTER(SemEval_2025_T2!$G$3:$G$100, REGEXMATCH(SemEval_2025_T2!$A$3:$A$100, ""(?i)"" & $F$19 &""_"" & $A23) )"),0.2892) -> 0.2892 | G23: =IFERROR(__xludf.DUMMYFUNCTION("FILTER(SemEval_2025_T2!$H$3:$H$100, REGEXMATCH(SemEval_2025_T2!$A$3:$A$100, ""(?i)"" & $F$19 &""_"" & $A23) )"),0.16) -> 0.16 | H23: =IFERROR(__xludf.DUMMYFUNCTION("FILTER(SemEval_2025_T2!$G$3:$G$100, REGEXMATCH(SemEval_2025_T2!$A$3:$A$100, ""(?i)"" & $H$19 &""_"" & $A23) )"),0.1274) -> 0.1274 | I23: =IFERROR(__xludf.DUMMYFUNCTION("FILTER(SemEval_2025_T2!$H$3:$H$100, REGEXMATCH(SemEval_2025_T2!$A$3:$A$100, ""(?i)"" & $H$19 &""_"" & $A23) )"),0.0496) -> 0.0496
A24: delta_gpt_title | B24: =B20-B23 -> 0.0442 | C24: =C20-C23 -> 0.0288 | D24: =D20-D23 -> 0.0658 | E24: =E20-E23 -> 0.0512 | F24: =F20-F23 -> 0.0542 | G24: =G20-G23 -> 0.0524 | H24: =H20-H23 -> 0.0392 | I24: =I20-I23 -> 0.056 | J24: =AVERAGE(B24,D24,F24,H24) -> 0.05085 | K24: =AVERAGE(C24,E24,G24,I24) -> 0.0471 | L24: =AVERAGE(J24,K24) -> 0.048975
A25: title_description | B25: =IFERROR(__xludf.DUMMYFUNCTION("FILTER(SemEval_2025_T2!$G$3:$G$100, REGEXMATCH(SemEval_2025_T2!$A$3:$A$100, ""(?i)"" & $B$19 &""_"" & $A25), NOT(REGEXMATCH(SemEval_2025_T2!$A$3:$A$100, ""(?i)complete"")) )"),0.4852) -> 0.4852 | C25: =IFERROR(__xludf.DUMMYFUNCTION("FILTER(SemEval_2025_T2!$H$3:$H$100, REGEXMATCH(SemEval_2025_T2!$A$3:$A$100, ""(?i)"" & $B$19 &""_"" & $A25), NOT(REGEXMATCH(SemEval_2025_T2!$A$3:$A$100, ""(?i)complete"")) )"),0.3286) -> 0.3286 | D25: =IFERROR(__xludf.DUMMYFUNCTION("FILTER(SemEval_2025_T2!$G$3:$G$100, REGEXMATCH(SemEval_2025_T2!$A$3:$A$100, ""(?i)"" & $D$19 &""_"" & $A25), NOT(REGEXMATCH(SemEval_2025_T2!$A$3:$A$100, ""(?i)complete"")) )"),0.3592) -> 0.3592 | E25: =IFERROR(__xludf.DUMMYFUNCTION("FILTER(SemEval_2025_T2!$H$3:$H$100, REGEXMATCH(SemEval_2025_T2!$A$3:$A$100, ""(?i)"" & $D$19 &""_"" & $A25), NOT(REGEXMATCH(SemEval_2025_T2!$A$3:$A$100, ""(?i)complete"")) )"),0.2508) -> 0.2508 | F25: =IFERROR(__xludf.DUMMYFUNCTION("FILTER(SemEval_2025_T2!$G$3:$G$100, REGEXMATCH(SemEval_2025_T2!$A$3:$A$100, ""(?i)"" & $F$19 &""_"" & $A25), NOT(REGEXMATCH(SemEval_2025_T2!$A$3:$A$100, ""(?i)complete"")) )"),0.3106) -> 0.3106 | G25: =IFERROR(__xludf.DUMMYFUNCTION("FILTER(SemEval_2025_T2!$H$3:$H$100, REGEXMATCH(SemEval_2025_T2!$A$3:$A$100, ""(?i)"" & $F$19 &""_"" & $A25), NOT(REGEXMATCH(SemEval_2025_T2!$A$3:$A$100, ""(?i)complete"")) )"),0.1764) -> 0.1764 | H25: =IFERROR(__xludf.DUMMYFUNCTION("FILTER(SemEval_2025_T2!$G$3:$G$100, REGEXMATCH(SemEval_2025_T2!$A$3:$A$100, ""(?i)"" & $H$19 &""_"" & $A25), NOT(REGEXMATCH(SemEval_2025_T2!$A$3:$A$100, ""(?i)complete"")) )"),0.1246) -> 0.1246 | I25: =IFERROR(__xludf.DUMMYFUNCTION("FILTER(SemEval_2025_T2!$H$3:$H$100, REGEXMATCH(SemEval_2025_T2!$A$3:$A$100, ""(?i)"" & $H$19 &""_"" & $A25), NOT(REGEXMATCH(SemEval_2025_T2!$A$3:$A$100, ""(?i)complete"")) )"),0.0576) -> 0.0576
A26: delta_own_description | B26: =B20-B25 -> 0.0032 | C26: =C20-C25 -> -0.0188 | D26: =D20-D25 -> 0.0622 | E26: =E20-E25 -> 0.0354 | F26: =F20-F25 -> 0.0328 | G26: =G20-G25 -> 0.036 | H26: =H20-H25 -> 0.042 | I26: =I20-I25 -> 0.048 | J26: =AVERAGE(B26,D26,F26,H26) -> 0.03505 | K26: =AVERAGE(C26,E26,G26,I26) -> 0.02515 | L26: =AVERAGE(J26,K26) -> 0.0301
A27: gpt_title_description | B27: =IFERROR(__xludf.DUMMYFUNCTION("FILTER(SemEval_2025_T2!$G$3:$G$100, REGEXMATCH(SemEval_2025_T2!$A$3:$A$100, ""(?i)"" & $B$19 &""_"" & $A27), NOT(REGEXMATCH(SemEval_2025_T2!$A$3:$A$100, ""(?i)complete"")) )"),0.4684) -> 0.4684 | C27: =IFERROR(__xludf.DUMMYFUNCTION("FILTER(SemEval_2025_T2!$H$3:$H$100, REGEXMATCH(SemEval_2025_T2!$A$3:$A$100, ""(?i)"" & $B$19 &""_"" & $A27), NOT(REGEXMATCH(SemEval_2025_T2!$A$3:$A$100, ""(?i)complete"")) )"),0.3222) -> 0.3222 | D27: =IFERROR(__xludf.DUMMYFUNCTION("FILTER(SemEval_2025_T2!$G$3:$G$100, REGEXMATCH(SemEval_2025_T2!$A$3:$A$100, ""(?i)"" & $D$19 &""_"" & $A27), NOT(REGEXMATCH(SemEval_2025_T2!$A$3:$A$100, ""(?i)complete"")) )"),0.383) -> 0.383 | E27: =IFERROR(__xludf.DUMMYFUNCTION("FILTER(SemEval_2025_T2!$H$3:$H$100, REGEXMATCH(SemEval_2025_T2!$A$3:$A$100, ""(?i)"" & $D$19 &""_"" & $A27), NOT(REGEXMATCH(SemEval_2025_T2!$A$3:$A$100, ""(?i)complete"")) )"),0.267599999999999) -> 0.2676 | F27: =IFERROR(__xludf.DUMMYFUNCTION("FILTER(SemEval_2025_T2!$G$3:$G$100, REGEXMATCH(SemEval_2025_T2!$A$3:$A$100, ""(?i)"" & $F$19 &""_"" & $A27), NOT(REGEXMATCH(SemEval_2025_T2!$A$3:$A$100, ""(?i)complete"")) )"),0.3124) -> 0.3124 | G27: =IFERROR(__xludf.DUMMYFUNCTION("FILTER(SemEval_2025_T2!$H$3:$H$100, REGEXMATCH(SemEval_2025_T2!$A$3:$A$100, ""(?i)"" & $F$19 &""_"" & $A27), NOT(REGEXMATCH(SemEval_2025_T2!$A$3:$A$100, ""(?i)complete"")) )"),0.177) -> 0.177 | H27: =IFERROR(__xludf.DUMMYFUNCTION("FILTER(SemEval_2025_T2!$G$3:$G$100, REGEXMATCH(SemEval_2025_T2!$A$3:$A$100, ""(?i)"" & $H$19 &""_"" & $A27), NOT(REGEXMATCH(SemEval_2025_T2!$A$3:$A$100, ""(?i)complete"")) )"),0.117799999999999) -> 0.1178 | I27: =IFERROR(__xludf.DUMMYFUNCTION("FILTER(SemEval_2025_T2!$H$3:$H$100, REGEXMATCH(SemEval_2025_T2!$A$3:$A$100, ""(?i)"" & $H$19 &""_"" & $A27), NOT(REGEXMATCH(SemEval_2025_T2!$A$3:$A$100, ""(?i)complete"")) )"),0.0406) -> 0.0406
A28: delta_gpt_description | B28: =B20-B27 -> 0.02 | C28: =C20-C27 -> -0.0124 | D28: =D20-D27 -> 0.0384 | E28: =E20-E27 -> 0.0186 | F28: =F20-F27 -> 0.031 | G28: =G20-G27 -> 0.0354 | H28: =H20-H27 -> 0.0488 | I28: =I20-I27 -> 0.065 | J28: =AVERAGE(B28,D28,F28,H28) -> 0.03455 | K28: =AVERAGE(C28,E28,G28,I28) -> 0.02665 | L28: =AVERAGE(J28,K28) -> 0.0306
